Workbook

Sheet Overtime
F2: BẢNG TĂNG CA THÁNG 06/ OVERTIME TABLE JUNE
A5: No./ STT | B5: Employee ID / Mã nhân viên | C5: Employee ID / Mã nhân viên | D5: Name / Tên nhân viên | E5: Dept/ Bộ phận | F5: Position/ Chức vụ | G5: Start Date Ngày bắt đầu làm việc | H5: 46163 | I5: 46164 | J5: 46165 | K5: 46166 | L5: 46167 | M5: 46168 | N5: 46169 | O5: 46170 | P5: 46171 | Q5: 46172 | R5: 46173 | S5: 46174 | T5: 46175 | U5: 46176 | V5: 46177 | W5: 46178 | X5: 46179 | Y5: 46180 | Z5: 46181 | AA5: 46182 | AB5: 46183 | AC5: 46184 | AD5: 46185 | AE5: 46186 | AF5: 46187 | AG5: 46188 | AH5: 46189 | AI5: 46190 | AJ5: 46191 | AK5: 46192 | AL5: 46193 | AM5: Normal Overtime/ Tăng ca ban ngày ngày thường | AN5: Night OT / Tăng ca đêm ngày thường | AO5: Weekly Overtime/ Tăng ca ngày nghỉ hàng tuần | AP5: Night weekly Overtime/ Tăng ca đêm ngày nghỉ hàng tuần | AQ5: Month/ Tháng | AR5: Year/ Năm | AS5: Remarks/ Ghi chú
H6: Thu | I6: Fri | J6: Sat | K6: Sun | L6: Mon | M6: Tue | N6: Wed | O6: Thu | P6: Fri | Q6: Sat | R6: Sun | S6: Mon | T6: Tue | U6: Wed | V6: Thu | W6: Fri | X6: Sat | Y6: Sun | Z6: Mon | AA6: Tue | AB6: Wed | AC6: Thu | AD6: Fri | AE6: Sat | AF6: Sun | AG6: Mon | AH6: Tue | AI6: Wed | AJ6: Thu | AK6: Fri | AL6: Sat
H7: T5 | I7: T6 | J7: T7 | K7: CN | L7: T2 | M7: T3 | N7: T4 | O7: T5 | P7: T6 | Q7: T7 | R7: CN | S7: T2 | T7: T3 | U7: T4 | V7: T5 | W7: T6 | X7: T7 | Y7: CN | Z7: T2 | AA7: T3 | AB7: T4 | AC7: T5 | AD7: T6 | AE7: T7 | AF7: CN | AG7: T2 | AH7: T3 | AI7: T4 | AJ7: T5 | AK7: T6 | AL7: T7
A8: 1 | B8: LEP001 | C8: 1013789 | D8: Hồ Mỹ Phương | E8: Finance | F8: Finance & Accounting Manager | G8: 28/04/2025 | AM8: =SUM(H8:AL8)-AN8-AO8 -> 0 | AO8: =J8+K8+Q8+R8+X8+Y8+AE8+AL8 -> 0 | AQ8: 6 | AR8: 2026
A9: 2 | B9: LEP003 | C9: 1014016 | D9: Nguyễn Cang | E9: Production | F9: Production Supervisor | G9: 26/05/2025 | J9: 8.5 | Q9: 8.5 | X9: 8.5 | AM9: =SUM(H9:AL9)-AN9-AO9 -> 0 | AO9: =J9+K9+Q9+R9+X9+Y9+AE9+AL9 -> 25.5 | AQ9: 6 | AR9: 2026
A10: 3 | B10: LEP004 | C10: 1014096 | D10: Lê Thành Hưng | E10: EHS | F10: EHS Engineer | G10: 09/06/2025 | AM10: =SUM(H10:AL10)-AN10-AO10 -> 0 | AO10: =J10+K10+Q10+R10+X10+Y10+AE10+AL10 -> 0 | AQ10: 6 | AR10: 2026
A11: 4 | B11: LEP005 | D11: Tô Văn Thiện | E11: Sales | F11: Sales Manager for S.E.A. | G11: 1/7/2025 | AM11: =SUM(H11:AL11)-AN11-AO11 -> 0 | AO11: =J11+K11+Q11+R11+X11+Y11+AE11+AL11 -> 0 | AQ11: 6 | AR11: 2026
A12: 6 | B12: LEP007 | C12: 1014338 | D12: Phan Thị Hải Âu | E12: Finance | F12: Accountant | G12: 14/7/2025 | AM12: =SUM(H12:AL12)-AN12-AO12 -> 0 | AO12: =J12+K12+Q12+R12+X12+Y12+AE12+AL12 -> 0 | AQ12: 6 | AR12: 2026
A13: 7 | B13: LEP009 | C13: 1014359 | D13: Nguyễn Đăng Khoa | E13: Logistics | F13: Logistic Supervisor | G13: 21/7/2025 | AM13: =SUM(H13:AL13)-AN13-AO13 -> 0 | AO13: =J13+K13+Q13+R13+X13+Y13+AE13+AL13 -> 0 | AQ13: 6 | AR13: 2026
A14: 8 | B14: LEP010 | D14: Trịnh Đình Tâm | E14: WH | F14: Riveting Forklift Driver | G14: 4/8/2025 | H14: 2 | I14: 4 | J14: 2 | K14: 8 | L14: 1 | M14: 2 | N14: 2 | O14: 4 | P14: 7 | Q14: 2 | T14: 2 | U14: 4 | V14: 2 | W14: 2 | X14: 4 | Z14: 2 | AA14: 2 | AB14: 2 | AC14: 2 | AD14: 2 | AE14: 2 | AF14: 8 | AG14: 2 | AH14: 2 | AI14: 2 | AJ14: 4 | AK14: 2 | AL14: 2 | AM14: =SUM(H14:AL14)-AN14-AO14 -> 65 | AN14: 1 | AO14: =K14+R14+Y14+AF14 -> 16 | AQ14: 6 | AR14: 2026
A15: 9 | B15: LEP011 | D15: Phạm Thanh Hiệp | E15: Logistics | F15: Customer Service Representative | G15: 4/8/2025 | AM15: =SUM(H15:AL15)-AN15-AO15 -> 0 | AO15: =K15+R15+Y15+AF15 -> 0 | AQ15: 6 | AR15: 2026
A16: 10 | B16: LEP012 | D16: Nguyễn Bảo Xuân Khôi | E16: HR | F16: HR & Admin Manager | G16: 11/8/2025 | AM16: =SUM(H16:AL16)-AN16-AO16 -> 0 | AO16: =K16+R16+Y16+AF16 -> 0 | AQ16: 6 | AR16: 2026
A17: 11 | B17: LEP013 | D17: Dương Hồ Nhã Vi | E17: QC | F17: Quality Team Leader | G17: 11/8/2025 | AM17: =SUM(H17:AL17)-AN17-AO17 -> 0 | AO17: =K17+R17+Y17+AF17 -> 0 | AQ17: 6 | AR17: 2026
A18: 12 | B18: LEP014 | D18: Phạm Hoàng Dinh | E18: Production | F18: Riveting Team leader | G18: 12/8/2025 | L18: 4 | M18: 4 | N18: 4 | O18: 4 | P18: 4 | S18: 4 | X18: 1 | AA18: 3 | AM18: =SUM(H18:AL18)-AN18-AO18 -> 28 | AO18: =K18+R18+Y18+AF18 -> 0 | AQ18: 6 | AR18: 2026
A19: 13 | B19: LEP018 | D19: Thạch Bạch Tra | E19: WH | F19: Warehouse Forklift Driver | G19: 18/8/2025 | I19: 4 | J19: 4 | K19: 8 | L19: 2 | M19: 2 | N19: 2 | O19: 4 | P19: 2 | Q19: 2 | R19: 8 | S19: 2 | T19: 4 | U19: 4 | V19: 4 | W19: 4 | Z19: 2 | AA19: 2 | AE19: 2 | AG19: 2 | AH19: 2 | AI19: 2 | AK19: 2 | AM19: =SUM(H19:AL19)-AN19-AO19 -> 54 | AO19: =K19+R19+Y19+AF19 -> 16 | AQ19: 6 | AR19: 2026
A20: 14 | B20: LEP022 | D20: Sử Hữu Trí | E20: Production | F20: Riveting Line Operator | G20: 18/8/2025 | H20: 4 | I20: 4 | J20: 4 | M20: 4 | O20: 4 | S20: 4 | T20: 4 | U20: 4 | W20: 4 | Z20: 2 | AA20: 4 | AC20: 2 | AD20: 4 | AH20: 4 | AI20: 4 | AL20: 4 | AM20: =SUM(H20:AL20)-AN20-AO20 -> 60 | AO20: =K20+R20+Y20+AF20 -> 0 | AQ20: 6 | AR20: 2026
A21: 15 | B21: LEP023 | D21: Phạm Thị Ánh Hồng | E21: Logistics | F21: Customer Service Representative | G21: 20/8/2025 | AM21: =SUM(H21:AL21)-AN21-AO21 -> 0 | AO21: =K21+R21+Y21+AF21 -> 0 | AQ21: 6 | AR21: 2026
A22: 16 | B22: LEP026 | D22: Nguyễn Bá Trinh | E22: WH | F22: WH Operator | G22: 21/8/2025 | I22: 4 | J22: 4 | K22: 8 | L22: 4 | M22: 4 | N22: 4 | O22: 4 | P22: 4 | Q22: 4 | R22: 8 | S22: 4 | T22: 4 | U22: 4 | V22: 4 | W22: 4 | X22: 4 | Z22: 4 | AA22: 2 | AB22: 2 | AC22: 2 | AD22: 4 | AE22: 2 | AF22: 8 | AG22: 2 | AJ22: 4 | AM22: =SUM(H22:AL22)-AN22-AO22 -> 78 | AO22: =K22+R22+Y22+AF22 -> 24 | AQ22: 6 | AR22: 2026
A23: 17 | B23: LEP027 | D23: Nguyễn Vũ Nguyệt Anh | E23: QC | F23: QC Inspector | G23: 25/8/2025 | H23: 4.5 | I23: 4.5 | J23: 5.5 | K23: 8 | O23: 4 | P23: 7 | Q23: 4 | R23: 8 | S23: 4 | T23: 4.5 | U23: 4 | V23: 2.5 | W23: 3 | X23: 4.5 | Z23: 4 | AA23: 4 | AB23: 4 | AC23: 5 | AD23: 4 | AE23: 3 | AG23: 4.5 | AH23: 4 | AJ23: 4.5 | AK23: 4 | AL23: 2.5 | AM23: =SUM(H23:AL23)-AN23-AO23 -> 95.5 | AO23: =K23+R23+Y23+AF23 -> 16 | AQ23: 6 | AR23: 2026
A24: 18 | B24: LEP028 | D24: Mã Hén Chiêu | E24: WH | F24: WH Staff | G24: 26/8/2025 | H24: 4 | I24: 2 | J24: 2 | K24: 8 | L24: 2 | M24: 2 | N24: 4 | O24: 2 | P24: 2 | Q24: 2 | R24: 8 | S24: 2 | T24: 2 | U24: 2 | V24: 2 | W24: 2 | Z24: 2 | AA24: 2 | AB24: 2 | AD24: 2 | AE24: 2 | AG24: 2 | AH24: 2 | AI24: 2 | AK24: 2 | AM24: =SUM(H24:AL24)-AN24-AO24 -> 50 | AO24: =K24+R24+Y24+AF24 -> 16 | AQ24: 6 | AR24: 2026
A25: 19 | B25: LEP029 | D25: Nguyễn Phương Nam | E25: WH | F25: WH Forklift Driver | G25: 26/8/2025 | H25: 2 | I25: 2 | J25: 0.5 | K25: 8 | L25: 4 | M25: 2 | N25: 2 | O25: 2 | P25: 4 | Q25: 4 | R25: 8 | T25: 2 | U25: 2 | V25: 2 | W25: 4 | X25: 2 | Z25: 4 | AA25: 2 | AB25: 4 | AE25: 2 | AG25: 2 | AH25: 2 | AI25: 2 | AK25: 2 | AM25: =SUM(H25:AL25)-AN25-AO25 -> 54.5 | AO25: =K25+R25+Y25+AF25 -> 16 | AQ25: 6 | AR25: 2026
A26: 20 | B26: LEP031 | D26: Dương Tấn Thanh | E26: WH | F26: WH Operator | G26: 29/8/2025 | H26: 2 | I26: 2 | J26: 2 | K26: 8 | L26: 2 | M26: 2 | N26: 2 | O26: 2 | P26: 2 | R26: 8 | S26: 2 | T26: 2 | U26: 2 | V26: 2 | X26: 2 | Z26: 2 | AA26: 2 | AD26: 2 | AE26: 2 | AG26: 2 | AI26: 2 | AK26: 2 | AM26: =SUM(H26:AL26)-AN26-AO26 -> 40 | AO26: =K26+R26+Y26+AF26 -> 16 | AQ26: 6 | AR26: 2026
A27: 22 | B27: LEP036 | D27: Hà Văn Sáng | E27: WH | F27: WH Forklift Driver | G27: 45878 | H27: 2 | I27: 2 | J27: 2 | K27: 8 | L27: 4 | M27: 2 | N27: 2 | O27: 2 | P27: 2 | Q27: 4 | R27: 8 | S27: 2 | T27: 2 | U27: 2 | V27: 2 | W27: 2 | X27: 2 | Z27: 2 | AB27: 2 | AC27: 2 | AD27: 2 | AE27: 2 | AG27: 2 | AH27: 2 | AI27: 2 | AK27: 2 | AM27: =SUM(H27:AL27)-AN27-AO27 -> 52 | AO27: =K27+R27+Y27+AF27 -> 16 | AQ27: 6 | AR27: 2026
A28: 23 | B28: LEP040 | D28: Dương Văn Thành | E28: Finance | F28: Branch IT Administrator | G28: 15/09/2025 | AM28: =SUM(H28:AL28)-AN28-AO28 -> 0 | AO28: =K28+R28+Y28+AF28 -> 0 | AQ28: 6 | AR28: 2026
A29: 24 | B29: LEP044 | D29: Lâm Văn Gấm | E29: Production | F29: Riveting Line Operator | G29: 16/09/2025 | H29: 4 | I29: 5 | J29: 5 | K29: 8 | L29: 4 | M29: 4 | N29: 4 | O29: 4 | P29: 4 | Q29: 4 | S29: 2 | T29: 4 | U29: 5 | AM29: =SUM(H29:AL29)-AN29-AO29 -> 49 | AO29: =K29+R29+Y29+AF29 -> 8 | AQ29: 6 | AR29: 2026
A30: 25 | B30: LEP045 | D30: Huỳnh Hoài Thương | E30: Production | F30: Riveting Line Operator | G30: 17/09/2025 | H30: 4 | K30: 8 | M30: 4 | O30: 6 | AM30: =SUM(H30:AL30)-AN30-AO30 -> 14 | AO30: =K30+R30+Y30+AF30 -> 8 | AQ30: 6 | AR30: 2026
A31: 26 | B31: LEP048 | D31: Phan Phước Tài | E31: Maintenance (PRO) | F31: Mechanical Maintenance Specialist | G31: 25/09/2025 | H31: 4 | I31: 4 | J31: 4 | L31: 4 | M31: 4 | N31: 4 | O31: 4 | P31: 4 | R31: 4 | V31: 4 | AB31: 4 | AC31: 3 | AH31: 2 | AI31: 4 | AL31: 4 | AM31: =SUM(H31:AL31)-AN31-AO31 -> 53 | AO31: =K31+R31+Y31+AF31 -> 4 | AQ31: 6 | AR31: 2026
A32: 27 | B32: LEP049 | D32: Ngô Viết Đức | E32: Maintenance (PRO) | F32: Electrical Maintenance Specialist | G32: 25/09/2025 | H32: 4 | I32: 4 | K32: 8 | M32: 2 | N32: 3 | O32: 4 | P32: 4 | R32: 4 | U32: 2 | V32: 2 | W32: 2 | X32: 2 | Z32: 6 | AC32: 4 | AE32: 2 | AH32: 2 | AI32: 4 | AK32: 2 | AM32: =SUM(H32:AL32)-AN32-AO32 -> 49 | AO32: =K32+R32+Y32+AF32 -> 12 | AQ32: 6 | AR32: 2026
A33: 28 | B33: LEP051 | D33: Nguyễn Văn Hiền | E33: Production | F33: Painting Line Teamleader | G33: 26/09/2025 | S33: 2 | T33: 4 | U33: 4 | X33: 3 | AB33: 4 | AC33: 2 | AG33: 1 | AH33: 2 | AJ33: 1 | AL33: 2 | AM33: =SUM(H33:AL33)-AN33-AO33 -> 25 | AO33: =K33+R33+Y33+AF33 -> 0 | AQ33: 6 | AR33: 2026
A34: 29 | B34: LEP052 | D34: Nguyễn Nam Bình | E34: Production | F34: Riveting Line Operator | G34: 30/09/2025 | H34: 4 | N34: 4 | O34: 4 | P34: 4 | AM34: =SUM(H34:AL34)-AN34-AO34 -> 16 | AO34: =K34+R34+Y34+AF34 -> 0 | AQ34: 6 | AR34: 2026
A35: 30 | B35: LEP054 | D35: Cao Ngọc Linh | E35: Maintenance (PRO) | F35: Environmental Protection Equipment | G35: 01/10/2025 | H35: 6 | I35: 6 | J35: 6 | L35: 2 | M35: 4 | N35: 6 | P35: 6 | S35: 6 | T35: 4 | U35: 6 | W35: 4 | X35: 6 | Z35: 2 | AA35: 4 | AB35: 4 | AC35: 4 | AD35: 5 | AE35: 4 | AG35: 4 | AH35: 4 | AI35: 4 | AJ35: 4 | AK35: 4 | AL35: 4 | AM35: =SUM(H35:AL35)-AN35-AO35 -> 109 | AO35: =K35+R35+Y35+AF35 -> 0 | AQ35: 6 | AR35: 2026
A36: 31 | B36: LEP056 | D36: Đỗ Thế Tài | E36: Production | F36: Painting Line Operator | G36: 02/10/2025 | H36: 6 | I36: 6 | J36: 2 | L36: 6 | M36: 5 | N36: 6 | O36: 6 | P36: 9 | R36: 8 | S36: 5 | T36: 4 | U36: 6 | V36: 2 | X36: 6 | Z36: 4 | AA36: 6 | AB36: 6 | AC36: 4 | AD36: 6 | AE36: 4 | AG36: 4 | AH36: 4 | AI36: 4 | AJ36: 4 | AK36: 4 | AL36: 4 | AM36: =SUM(H36:AL36)-AN36-AO36 -> 122 | AN36: 1 | AO36: =K36+R36+Y36+AF36 -> 8 | AQ36: 6 | AR36: 2026
A37: 32 | B37: LEP057 | D37: Lâm Thanh Hiếu | E37: Production | F37: Painting Line Operator | G37: 02/10/2025 | H37: 6 | I37: 6 | J37: 4 | L37: 2 | M37: 4 | N37: 6 | O37: 6 | P37: 6 | Q37: 2 | S37: 6 | T37: 4 | U37: 6 | V37: 2 | W37: 6 | X37: 6 | Z37: 4 | AA37: 6 | AB37: 4 | AC37: 6 | AD37: 5 | AE37: 4 | AG37: 6 | AH37: 4 | AI37: 4 | AJ37: 4 | AK37: 4 | AL37: 4 | AM37: =SUM(H37:AL37)-AN37-AO37 -> 127 | AO37: =K37+R37+Y37+AF37 -> 0 | AQ37: 6 | AR37: 2026
A38: 35 | B38: LEP061 | D38: Nguyễn Văn Tình | E38: Production | F38: Riveting Line Operator | G38: 04/10/2025 | I38: 5 | J38: 2 | K38: 8 | M38: 4 | N38: 4 | O38: 4 | P38: 4 | Q38: 4 | S38: 1 | T38: 1 | U38: 1 | AM38: =SUM(H38:AL38)-AN38-AO38 -> 30 | AO38: =K38+R38+Y38+AF38 -> 8 | AQ38: 6 | AR38: 2026
A39: 36 | B39: LEP062 | D39: Dương Trung Toàn | E39: Production | F39: Riveting Line Operator | G39: 04/10/2025 | H39: 4 | I39: 5 | M39: 4 | N39: 4 | O39: 4 | P39: 4 | Q39: 4 | S39: 1 | T39: 5 | U39: 1 | X39: 3 | AB39: 4 | AC39: 2 | AG39: 1 | AH39: 2 | AJ39: 1 | AL39: 2 | AM39: =SUM(H39:AL39)-AN39-AO39 -> 51 | AO39: =K39+R39+Y39+AF39 -> 0 | AQ39: 6 | AR39: 2026
A40: 39 | B40: LEP067 | D40: H Nguel Kbuor | E40: Production | F40: Painting Line Operator | G40: 07/10/2025 | H40: 5 | I40: 4 | J40: 5 | K40: 8 | L40: 4 | M40: 4 | N40: 4 | O40: 4 | T40: 4 | U40: 1 | X40: 3 | AC40: 2 | AL40: 4 | AM40: =SUM(H40:AL40)-AN40-AO40 -> 44 | AO40: =K40+R40+Y40+AF40 -> 8 | AQ40: 6 | AR40: 2026
A41: 40 | B41: LEP068 | D41: Y in Zơ Kbuor | E41: Production | F41: Riveting Line Operator | G41: 07/10/2025 | I41: 4 | J41: 1 | N41: 4 | O41: 4 | P41: 4 | U41: 4 | AM41: =SUM(H41:AL41)-AN41-AO41 -> 21 | AO41: =K41+R41+Y41+AF41 -> 0 | AQ41: 6 | AR41: 2026
A42: 41 | B42: LEP069 | D42: Siu Nhoát | E42: Production | F42: Riveting Line Operator | G42: 07/10/2025 | H42: 5 | I42: 4 | J42: 5 | K42: 8 | L42: 4 | M42: 4 | N42: 4 | O42: 4 | P42: 4 | Q42: 4 | S42: 2 | T42: 4 | U42: 1 | X42: 3 | AM42: =SUM(H42:AL42)-AN42-AO42 -> 48 | AO42: =K42+R42+Y42+AF42 -> 8 | AQ42: 6 | AR42: 2026
A43: 42 | B43: LEP073 | D43: Y Sion Kbuor | E43: Production | F43: Riveting Line Operator | G43: 13/10/2025 | H43: 5 | I43: 5 | J43: 5 | K43: 8 | L43: 4 | M43: 4 | N43: 4 | O43: 4 | P43: 4 | Q43: 4 | S43: 2 | U43: 4 | AC43: 2 | AM43: =SUM(H43:AL43)-AN43-AO43 -> 47 | AO43: =K43+R43+Y43+AF43 -> 8 | AQ43: 6 | AR43: 2026
...

Sheet OT1
F2: BẢNG TĂNG CA THÁNG 08/ OVERTIME TABLE AUGUST
A5: No./ STT | B5: Employee ID / Mã nhân viên | C5: Employee ID / Mã nhân viên | D5: Name / Tên nhân viên | E5: Dept/ Bộ phận | F5: Position/ Chức vụ | G5: Start Date Ngày bắt đầu làm việc | H5: 46224 | I5: 46225 | J5: 46226 | K5: 46227 | L5: 46228 | M5: 46229 | N5: 46230 | O5: 46231 | P5: 46232 | Q5: 46233 | R5: 46234 | S5: 46235 | T5: 46236 | U5: 46237 | V5: 46238 | W5: 46239 | X5: 46240 | Y5: 46241 | Z5: 46242 | AA5: 46243 | AB5: 46244 | AC5: 46245 | AD5: 46246 | AE5: 46247 | AF5: 46248 | AG5: 46249 | AH5: 46250 | AI5: 46251 | AJ5: 46252 | AK5: 46253 | AL5: 46254 | AM5: Total Standard WD/ Tổng số ngày công chuẩn trong tháng | AN5: Total WD / Tồng số ngày làm việc thực tế | AO5: Total AL / Tồng số ngày nghỉ phép năm | AP5: Total UL/ Tồng số ngày nghỉ không lương | AQ5: Total PH/ Tồng số ngày nghỉ lễ | AR5: Total SL/ Tồng số ngày nghỉ ốm | AS5: Total PL/ Nghỉ hưởng lương theo luật như cha mẹ mất, kết hôn | AT5: Số ngày làm việc ban đêm / Số ngày làm việc ban đêm | AU5: Early leaving going late / Đi trễ về sớm | AV5: Performance Bonus/Tiền thưởng năng suất | AW5: Performance Bonus Allowance/ Tiền chuyên cần | AX5: Hazardous Allowance/ Tiền độc hại | AY5: Firefighting Allowance / Tiền trợ cấp PCCC | AZ5: Other fees / Các chi phí khác trong tháng | BA5: Trade Union fee / Trừ tiền đoàn phí | BB5: Month/ Tháng | BC5: Year/ Năm | BD5: Remarks/ Ghi chú
H6: Tue | I6: Wed | J6: Thu | K6: Fri | L6: Sat | M6: Sun | N6: Mon | O6: Tue | P6: Wed | Q6: Thu | R6: Fri | S6: Sat | T6: Sun | U6: Mon | V6: Tue | W6: Wed | X6: Thu | Y6: Fri | Z6: Sat | AA6: Sun | AB6: Mon | AC6: Tue | AD6: Wed | AE6: Thu | AF6: Fri | AG6: Sat | AH6: Sun | AI6: Mon | AJ6: Tue | AK6: Wed | AL6: Thu
H7: T3 | I7: T4 | J7: T5 | K7: T6 | L7: T7 | M7: CN | N7: T2 | O7: T3 | P7: T4 | Q7: T5 | R7: T6 | S7: T7 | T7: CN | U7: T2 | V7: T3 | W7: T4 | X7: T5 | Y7: T6 | Z7: T7 | AA7: CN | AB7: T2 | AC7: T3 | AD7: T4 | AE7: T5 | AF7: T6 | AG7: T7 | AH7: CN | AI7: T2 | AJ7: T3 | AK7: T4 | AL7: T5
A8: 1 | B8: LEP001 | C8: 1013789 | D8: Hồ Mỹ Phương | E8: Finance | F8: Finance & Accounting Manager | G8: 28/04/2025 | AN8: =COUNTIF(H8:AL8,"W")+COUNTIF(H8:AL8,"W/2")*0.5+COUNTIF(H8:AL8,"BT")+COUNTIF(H8:AL8,"N") -> 0 | AO8: =COUNTIF(H8:AL8,"AL") -> 0 | AP8: =COUNTIF(H8:AL8,"UL") -> 0 | AQ8: =COUNTIF(H8:AL8,"PH") -> 0 | AR8: =COUNTIF(H8:AL8,"SL") -> 0 | AS8: =COUNTIF(H8:AL8,"PL") -> 0 | BA8: -40000 | BB8: 8 | BC8: 2026
A9: 2 | B9: LEP004 | C9: 1014096 | D9: Lê Thành Hưng | E9: EHS | F9: EHS Engineer | G9: 09/06/2025 | AN9: =COUNTIF(H9:AL9,"W")+COUNTIF(H9:AL9,"W/2")*0.5+COUNTIF(H9:AL9,"BT")+COUNTIF(H9:AL9,"N") -> 0 | AO9: =COUNTIF(H9:AL9,"AL") -> 0 | AP9: =COUNTIF(H9:AL9,"UL") -> 0 | AQ9: =COUNTIF(H9:AL9,"PH") -> 0 | AR9: =COUNTIF(H9:AL9,"SL") -> 0 | AS9: =COUNTIF(H9:AL9,"PL") -> 0 | BA9: -40000 | BB9: 8 | BC9: 2026
A10: 3 | B10: LEP005 | D10: Tô Văn Thiện | E10: Sales | F10: Sales Manager for S.E.A. | G10: 1/7/2025 | AN10: =COUNTIF(H10:AL10,"W")+COUNTIF(H10:AL10,"W/2")*0.5+COUNTIF(H10:AL10,"BT")+COUNTIF(H10:AL10,"N") -> 0 | AO10: =COUNTIF(H10:AL10,"AL") -> 0 | AP10: =COUNTIF(H10:AL10,"UL") -> 0 | AQ10: =COUNTIF(H10:AL10,"PH") -> 0 | AR10: =COUNTIF(H10:AL10,"SL") -> 0 | AS10: =COUNTIF(H10:AL10,"PL") -> 0 | BA10: -40000 | BB10: 8 | BC10: 2026
A11: 4 | B11: LEP007 | C11: 1014338 | D11: Phan Thị Hải Âu | E11: Finance | F11: Accountant | G11: 14/7/2025 | AN11: =COUNTIF(H11:AL11,"W")+COUNTIF(H11:AL11,"W/2")*0.5+COUNTIF(H11:AL11,"BT")+COUNTIF(H11:AL11,"N") -> 0 | AO11: =COUNTIF(H11:AL11,"AL") -> 0 | AP11: =COUNTIF(H11:AL11,"UL") -> 0 | AQ11: =COUNTIF(H11:AL11,"PH") -> 0 | AR11: =COUNTIF(H11:AL11,"SL") -> 0 | AS11: =COUNTIF(H11:AL11,"PL") -> 0 | BA11: -40000 | BB11: 8 | BC11: 2026
A12: 5 | B12: LEP009 | C12: 1014359 | D12: Nguyễn Đăng Khoa | E12: Logistics | F12: Logistic Supervisor | G12: 21/7/2025 | AN12: =COUNTIF(H12:AL12,"W")+COUNTIF(H12:AL12,"W/2")*0.5+COUNTIF(H12:AL12,"BT")+COUNTIF(H12:AL12,"N") -> 0 | AO12: =COUNTIF(H12:AL12,"AL") -> 0 | AP12: =COUNTIF(H12:AL12,"UL") -> 0 | AQ12: =COUNTIF(H12:AL12,"PH") -> 0 | AR12: =COUNTIF(H12:AL12,"SL") -> 0 | AS12: =COUNTIF(H12:AL12,"PL") -> 0 | BA12: -40000 | BB12: 8 | BC12: 2026
A13: 6 | B13: LEP010 | D13: Trịnh Đình Tâm | E13: WH | F13: Riveting Forklift Driver | G13: 4/8/2025 | I13: 2 | J13: 2 | K13: 2 | M13: 8 | S13: 2 | U13: 2 | AG13: 2 | AJ13: 2 | AL13: 1 | AN13: =COUNTIF(H13:AL13,"W")+COUNTIF(H13:AL13,"W/2")*0.5+COUNTIF(H13:AL13,"BT")+COUNTIF(H13:AL13,"N") -> 0 | AO13: =COUNTIF(H13:AL13,"AL") -> 0 | AP13: =COUNTIF(H13:AL13,"UL") -> 0 | AQ13: =COUNTIF(H13:AL13,"PH") -> 0 | AR13: =COUNTIF(H13:AL13,"SL") -> 0 | AS13: =COUNTIF(H13:AL13,"PL") -> 0 | BA13: -40000 | BB13: 8 | BC13: 2026
A14: 7 | B14: LEP011 | D14: Phạm Thanh Hiệp | E14: Logistics | F14: Customer Service Representative | G14: 4/8/2025 | AN14: =COUNTIF(H14:AL14,"W")+COUNTIF(H14:AL14,"W/2")*0.5+COUNTIF(H14:AL14,"BT")+COUNTIF(H14:AL14,"N") -> 0 | AO14: =COUNTIF(H14:AL14,"AL") -> 0 | AP14: =COUNTIF(H14:AL14,"UL") -> 0 | AQ14: =COUNTIF(H14:AL14,"PH") -> 0 | AR14: =COUNTIF(H14:AL14,"SL") -> 0 | AS14: =COUNTIF(H14:AL14,"PL") -> 0 | BA14: -40000 | BB14: 8 | BC14: 2026
A15: 8 | B15: LEP014 | D15: Phạm Hoàng Dinh | E15: Production | F15: Riveting Team leader | G15: 12/8/2025 | L15: 1 | V15: 1 | AN15: =COUNTIF(H15:AL15,"W")+COUNTIF(H15:AL15,"W/2")*0.5+COUNTIF(H15:AL15,"BT")+COUNTIF(H15:AL15,"N") -> 0 | AO15: =COUNTIF(H15:AL15,"AL") -> 0 | AP15: =COUNTIF(H15:AL15,"UL") -> 0 | AQ15: =COUNTIF(H15:AL15,"PH") -> 0 | AR15: =COUNTIF(H15:AL15,"SL") -> 0 | AS15: =COUNTIF(H15:AL15,"PL") -> 0 | BA15: -40000 | BB15: 8 | BC15: 2026
A16: 9 | B16: LEP018 | D16: Thạch Bạch Tra | E16: WH | F16: Warehouse Forklift Driver | G16: 18/8/2025 | J16: 2 | K16: 2 | M16: 8 | AN16: =COUNTIF(H16:AL16,"W")+COUNTIF(H16:AL16,"W/2")*0.5+COUNTIF(H16:AL16,"BT")+COUNTIF(H16:AL16,"N") -> 0 | AO16: =COUNTIF(H16:AL16,"AL") -> 0 | AP16: =COUNTIF(H16:AL16,"UL") -> 0 | AQ16: =COUNTIF(H16:AL16,"PH") -> 0 | AR16: =COUNTIF(H16:AL16,"SL") -> 0 | AS16: =COUNTIF(H16:AL16,"PL") -> 0 | BA16: -40000 | BB16: 8 | BC16: 2026
A17: 10 | B17: LEP022 | D17: Sử Hữu Trí | E17: Production | F17: Riveting Line Operator | G17: 18/8/2025 | I17: 2 | Y17: 2 | AE17: 2 | AN17: =COUNTIF(H17:AL17,"W")+COUNTIF(H17:AL17,"W/2")*0.5+COUNTIF(H17:AL17,"BT")+COUNTIF(H17:AL17,"N") -> 0 | AO17: =COUNTIF(H17:AL17,"AL") -> 0 | AP17: =COUNTIF(H17:AL17,"UL") -> 0 | AQ17: =COUNTIF(H17:AL17,"PH") -> 0 | AR17: =COUNTIF(H17:AL17,"SL") -> 0 | AS17: =COUNTIF(H17:AL17,"PL") -> 0 | BA17: -40000 | BB17: 8 | BC17: 2026
A18: 11 | B18: LEP023 | D18: Phạm Thị Ánh Hồng | E18: Logistics | F18: Customer Service Representative | G18: 20/8/2025 | AN18: =COUNTIF(H18:AL18,"W")+COUNTIF(H18:AL18,"W/2")*0.5+COUNTIF(H18:AL18,"BT")+COUNTIF(H18:AL18,"N") -> 0 | AO18: =COUNTIF(H18:AL18,"AL") -> 0 | AP18: =COUNTIF(H18:AL18,"UL") -> 0 | AQ18: =COUNTIF(H18:AL18,"PH") -> 0 | AR18: =COUNTIF(H18:AL18,"SL") -> 0 | AS18: =COUNTIF(H18:AL18,"PL") -> 0 | BA18: -40000 | BB18: 8 | BC18: 2026
A19: 12 | B19: LEP026 | D19: Nguyễn Bá Trinh | E19: WH | F19: WH Operator | G19: 21/8/2025 | I19: 2 | J19: 2 | K19: 1 | M19: 8 | AN19: =COUNTIF(H19:AL19,"W")+COUNTIF(H19:AL19,"W/2")*0.5+COUNTIF(H19:AL19,"BT")+COUNTIF(H19:AL19,"N") -> 0 | AO19: =COUNTIF(H19:AL19,"AL") -> 0 | AP19: =COUNTIF(H19:AL19,"UL") -> 0 | AQ19: =COUNTIF(H19:AL19,"PH") -> 0 | AR19: =COUNTIF(H19:AL19,"SL") -> 0 | AS19: =COUNTIF(H19:AL19,"PL") -> 0 | BA19: -40000 | BB19: 8 | BC19: 2026
A20: 13 | B20: LEP027 | D20: Nguyễn Vũ Nguyệt Anh | E20: QC | F20: QC Inspector | G20: 25/8/2025 | U20: 2 | V20: 2.5 | W20: 2 | X20: 3 | Y20: 2 | AB20: 2 | AC20: 0.5 | AE20: 2 | AK20: 2 | AN20: =COUNTIF(H20:AL20,"W")+COUNTIF(H20:AL20,"W/2")*0.5+COUNTIF(H20:AL20,"BT")+COUNTIF(H20:AL20,"N") -> 0 | AO20: =COUNTIF(H20:AL20,"AL") -> 0 | AP20: =COUNTIF(H20:AL20,"UL") -> 0 | AQ20: =COUNTIF(H20:AL20,"PH") -> 0 | AR20: =COUNTIF(H20:AL20,"SL") -> 0 | AS20: =COUNTIF(H20:AL20,"PL") -> 0 | BA20: -40000 | BB20: 8 | BC20: 2026
A21: 14 | B21: LEP028 | D21: Mã Hén Chiêu | E21: WH | F21: WH Staff | G21: 26/8/2025 | J21: 2 | M21: 8 | Q21: 2 | AN21: =COUNTIF(H21:AL21,"W")+COUNTIF(H21:AL21,"W/2")*0.5+COUNTIF(H21:AL21,"BT")+COUNTIF(H21:AL21,"N") -> 0 | AO21: =COUNTIF(H21:AL21,"AL") -> 0 | AP21: =COUNTIF(H21:AL21,"UL") -> 0 | AQ21: =COUNTIF(H21:AL21,"PH") -> 0 | AR21: =COUNTIF(H21:AL21,"SL") -> 0 | AS21: =COUNTIF(H21:AL21,"PL") -> 0 | BA21: -40000 | BB21: 8 | BC21: 2026
A22: 15 | B22: LEP029 | D22: Nguyễn Phương Nam | E22: WH | F22: WH Forklift Driver | G22: 26/8/2025 | J22: 2 | K22: 2 | AN22: =COUNTIF(H22:AL22,"W")+COUNTIF(H22:AL22,"W/2")*0.5+COUNTIF(H22:AL22,"BT")+COUNTIF(H22:AL22,"N") -> 0 | AO22: =COUNTIF(H22:AL22,"AL") -> 0 | AP22: =COUNTIF(H22:AL22,"UL") -> 0 | AQ22: =COUNTIF(H22:AL22,"PH") -> 0 | AR22: =COUNTIF(H22:AL22,"SL") -> 0 | AS22: =COUNTIF(H22:AL22,"PL") -> 0 | BA22: -40000 | BB22: 8 | BC22: 2026
A23: 16 | B23: LEP031 | D23: Dương Tấn Thanh | E23: WH | F23: WH Operator | G23: 29/8/2025 | J23: 2 | K23: 2 | AN23: =COUNTIF(H23:AL23,"W")+COUNTIF(H23:AL23,"W/2")*0.5+COUNTIF(H23:AL23,"BT")+COUNTIF(H23:AL23,"N") -> 0 | AO23: =COUNTIF(H23:AL23,"AL") -> 0 | AP23: =COUNTIF(H23:AL23,"UL") -> 0 | AQ23: =COUNTIF(H23:AL23,"PH") -> 0 | AR23: =COUNTIF(H23:AL23,"SL") -> 0 | AS23: =COUNTIF(H23:AL23,"PL") -> 0 | BA23: -40000 | BB23: 8 | BC23: 2026
A24: 17 | B24: LEP036 | D24: Hà Văn Sáng | E24: WH | F24: WH Forklift Driver | G24: 45878 | I24: 2 | J24: 2 | K24: 2 | AN24: =COUNTIF(H24:AL24,"W")+COUNTIF(H24:AL24,"W/2")*0.5+COUNTIF(H24:AL24,"BT")+COUNTIF(H24:AL24,"N") -> 0 | AO24: =COUNTIF(H24:AL24,"AL") -> 0 | AP24: =COUNTIF(H24:AL24,"UL") -> 0 | AQ24: =COUNTIF(H24:AL24,"PH") -> 0 | AR24: =COUNTIF(H24:AL24,"SL") -> 0 | AS24: =COUNTIF(H24:AL24,"PL") -> 0 | BA24: -40000 | BB24: 8 | BC24: 2026
A25: 18 | B25: LEP040 | D25: Dương Văn Thành | E25: Finance | F25: Branch IT Administrator | G25: 15/09/2025 | AN25: =COUNTIF(H25:AL25,"W")+COUNTIF(H25:AL25,"W/2")*0.5+COUNTIF(H25:AL25,"BT")+COUNTIF(H25:AL25,"N") -> 0 | AO25: =COUNTIF(H25:AL25,"AL") -> 0 | AP25: =COUNTIF(H25:AL25,"UL") -> 0 | AQ25: =COUNTIF(H25:AL25,"PH") -> 0 | AR25: =COUNTIF(H25:AL25,"SL") -> 0 | AS25: =COUNTIF(H25:AL25,"PL") -> 0 | BA25: -40000 | BB25: 8 | BC25: 2026
A26: 19 | B26: LEP045 | D26: Huỳnh Hoài Thương | E26: Production | F26: Riveting Line Operator | G26: 17/09/2025 | Y26: 2 | BB26: 8 | BC26: 2026
A27: 20 | B27: LEP048 | D27: Phan Phước Tài | E27: Maintenance (PRO) | F27: Mechanical Maintenance Specialist | G27: 25/09/2025 | J27: 2 | M27: 9 | Q27: 2 | S27: 2 | T27: 8 | X27: 3 | AN27: =COUNTIF(H27:AL27,"W")+COUNTIF(H27:AL27,"W/2")*0.5+COUNTIF(H27:AL27,"BT")+COUNTIF(H27:AL27,"N") -> 0 | AO27: =COUNTIF(H27:AL27,"AL") -> 0 | AP27: =COUNTIF(H27:AL27,"UL") -> 0 | AQ27: =COUNTIF(H27:AL27,"PH") -> 0 | AR27: =COUNTIF(H27:AL27,"SL") -> 0 | AS27: =COUNTIF(H27:AL27,"PL") -> 0 | BA27: -40000 | BB27: 8 | BC27: 2026
A28: 21 | B28: LEP049 | D28: Ngô Viết Đức | E28: Maintenance (PRO) | F28: Electrical Maintenance Specialist | G28: 25/09/2025 | M28: 9 | R28: 2 | U28: 2 | V28: 2 | W28: 2 | Y28: 2 | AE28: 2 | AN28: =COUNTIF(H28:AL28,"W")+COUNTIF(H28:AL28,"W/2")*0.5+COUNTIF(H28:AL28,"BT")+COUNTIF(H28:AL28,"N") -> 0 | AO28: =COUNTIF(H28:AL28,"AL") -> 0 | AP28: =COUNTIF(H28:AL28,"UL") -> 0 | AQ28: =COUNTIF(H28:AL28,"PH") -> 0 | AR28: =COUNTIF(H28:AL28,"SL") -> 0 | AS28: =COUNTIF(H28:AL28,"PL") -> 0 | BA28: -40000 | BB28: 8 | BC28: 2026
A29: 22 | B29: LEP052 | D29: Nguyễn Nam Bình | E29: Production | F29: Riveting Line Operator | G29: 30/09/2025 | Y29: 2 | AN29: =COUNTIF(H29:AL29,"W")+COUNTIF(H29:AL29,"W/2")*0.5+COUNTIF(H29:AL29,"BT")+COUNTIF(H29:AL29,"N") -> 0 | AO29: =COUNTIF(H29:AL29,"AL") -> 0 | AP29: =COUNTIF(H29:AL29,"UL") -> 0 | AQ29: =COUNTIF(H29:AL29,"PH") -> 0 | AR29: =COUNTIF(H29:AL29,"SL") -> 0 | AS29: =COUNTIF(H29:AL29,"PL") -> 0 | BA29: -40000 | BB29: 8 | BC29: 2026
A30: 23 | B30: LEP054 | D30: Cao Ngọc Linh | E30: Maintenance (PRO) | F30: Environmental Protection Equipment | G30: 01/10/2025 | I30: 2 | N30: 2 | P30: 2 | Q30: 2 | S30: 1 | AB30: 2 | AE30: 2 | AG30: 1 | AJ30: 2 | AN30: =COUNTIF(H30:AL30,"W")+COUNTIF(H30:AL30,"W/2")*0.5+COUNTIF(H30:AL30,"BT")+COUNTIF(H30:AL30,"N") -> 0 | AO30: =COUNTIF(H30:AL30,"AL") -> 0 | AP30: =COUNTIF(H30:AL30,"UL") -> 0 | AQ30: =COUNTIF(H30:AL30,"PH") -> 0 | AR30: =COUNTIF(H30:AL30,"SL") -> 0 | AS30: =COUNTIF(H30:AL30,"PL") -> 0 | BA30: -40000 | BB30: 8 | BC30: 2026
A31: 24 | B31: LEP056 | D31: Đỗ Thế Tài | E31: Production | F31: Painting Line Operator | G31: 02/10/2025 | P31: 2 | Q31: 2 | W31: 2 | X31: 2 | AN31: =COUNTIF(H31:AL31,"W")+COUNTIF(H31:AL31,"W/2")*0.5+COUNTIF(H31:AL31,"BT")+COUNTIF(H31:AL31,"N") -> 0 | AO31: =COUNTIF(H31:AL31,"AL") -> 0 | AP31: =COUNTIF(H31:AL31,"UL") -> 0 | AQ31: =COUNTIF(H31:AL31,"PH") -> 0 | AR31: =COUNTIF(H31:AL31,"SL") -> 0 | AS31: =COUNTIF(H31:AL31,"PL") -> 0 | BA31: -40000 | BB31: 8 | BC31: 2026
A32: 25 | B32: LEP057 | D32: Lâm Thanh Hiếu | E32: Production | F32: Painting Line Operator | G32: 02/10/2025 | I32: 2 | J32: 2 | Q32: 2 | S32: 1 | AB32: 2 | AE32: 2 | AG32: 1 | AN32: =COUNTIF(H32:AL32,"W")+COUNTIF(H32:AL32,"W/2")*0.5+COUNTIF(H32:AL32,"BT")+COUNTIF(H32:AL32,"N") -> 0 | AO32: =COUNTIF(H32:AL32,"AL") -> 0 | AP32: =COUNTIF(H32:AL32,"UL") -> 0 | AQ32: =COUNTIF(H32:AL32,"PH") -> 0 | AR32: =COUNTIF(H32:AL32,"SL") -> 0 | AS32: =COUNTIF(H32:AL32,"PL") -> 0 | BA32: -40000 | BB32: 8 | BC32: 2026
A33: 26 | B33: LEP062 | D33: Dương Trung Toàn | E33: Production | F33: Riveting Line Operator | G33: 04/10/2025 | Y33: 2 | AE33: 2 | AN33: =COUNTIF(H33:AL33,"W")+COUNTIF(H33:AL33,"W/2")*0.5+COUNTIF(H33:AL33,"BT")+COUNTIF(H33:AL33,"N") -> 0 | AO33: =COUNTIF(H33:AL33,"AL") -> 0 | AP33: =COUNTIF(H33:AL33,"UL") -> 0 | AQ33: =COUNTIF(H33:AL33,"PH") -> 0 | AR33: =COUNTIF(H33:AL33,"SL") -> 0 | AS33: =COUNTIF(H33:AL33,"PL") -> 0 | BA33: -40000 | BB33: 8 | BC33: 2026
A34: 27 | B34: LEP067 | D34: H Nguel Kbuor | E34: Production | F34: Painting Line Operator | G34: 07/10/2025 | AN34: =COUNTIF(H34:AL34,"W")+COUNTIF(H34:AL34,"W/2")*0.5+COUNTIF(H34:AL34,"BT")+COUNTIF(H34:AL34,"N") -> 0 | AO34: =COUNTIF(H34:AL34,"AL") -> 0 | AP34: =COUNTIF(H34:AL34,"UL") -> 0 | AQ34: =COUNTIF(H34:AL34,"PH") -> 0 | AR34: =COUNTIF(H34:AL34,"SL") -> 0 | AS34: =COUNTIF(H34:AL34,"PL") -> 0 | BA34: -40000 | BB34: 8 | BC34: 2026
A35: 28 | B35: LEP068 | D35: Y in Zơ Kbuor | E35: Production | F35: Riveting Line Operator | G35: 07/10/2025 | Y35: 2 | AE35: 2 | AN35: =COUNTIF(H35:AL35,"W")+COUNTIF(H35:AL35,"W/2")*0.5+COUNTIF(H35:AL35,"BT")+COUNTIF(H35:AL35,"N") -> 0 | AO35: =COUNTIF(H35:AL35,"AL") -> 0 | AP35: =COUNTIF(H35:AL35,"UL") -> 0 | AQ35: =COUNTIF(H35:AL35,"PH") -> 0 | AR35: =COUNTIF(H35:AL35,"SL") -> 0 | AS35: =COUNTIF(H35:AL35,"PL") -> 0 | BA35: -40000 | BB35: 8 | BC35: 2026
A36: 29 | B36: LEP069 | D36: Siu Nhoát | E36: Production | F36: Riveting Line Operator | G36: 07/10/2025 | AN36: =COUNTIF(H36:AL36,"W")+COUNTIF(H36:AL36,"W/2")*0.5+COUNTIF(H36:AL36,"BT")+COUNTIF(H36:AL36,"N") -> 0 | AO36: =COUNTIF(H36:AL36,"AL") -> 0 | AP36: =COUNTIF(H36:AL36,"UL") -> 0 | AQ36: =COUNTIF(H36:AL36,"PH") -> 0 | AR36: =COUNTIF(H36:AL36,"SL") -> 0 | AS36: =COUNTIF(H36:AL36,"PL") -> 0 | BA36: -40000 | BB36: 8 | BC36: 2026
A37: 30 | B37: LEP073 | D37: Y Sion Kbuor | E37: Production | F37: Riveting Line Operator | G37: 13/10/2025 | Y37: 2 | AN37: =COUNTIF(H37:AL37,"W")+COUNTIF(H37:AL37,"W/2")*0.5+COUNTIF(H37:AL37,"BT")+COUNTIF(H37:AL37,"N") -> 0 | AO37: =COUNTIF(H37:AL37,"AL") -> 0 | AP37: =COUNTIF(H37:AL37,"UL") -> 0 | AQ37: =COUNTIF(H37:AL37,"PH") -> 0 | AR37: =COUNTIF(H37:AL37,"SL") -> 0 | AS37: =COUNTIF(H37:AL37,"PL") -> 0 | BA37: -40000 | BB37: 8 | BC37: 2026
A38: 31 | B38: LEP075 | D38: Trần Văn Trọn | E38: Production | F38: Riveting Line Operator | G38: 15/10/2025 | AN38: =COUNTIF(H38:AL38,"W")+COUNTIF(H38:AL38,"W/2")*0.5+COUNTIF(H38:AL38,"BT")+COUNTIF(H38:AL38,"N") -> 0 | AO38: =COUNTIF(H38:AL38,"AL") -> 0 | AP38: =COUNTIF(H38:AL38,"UL") -> 0 | AQ38: =COUNTIF(H38:AL38,"PH") -> 0 | AR38: =COUNTIF(H38:AL38,"SL") -> 0 | AS38: =COUNTIF(H38:AL38,"PL") -> 0 | BA38: -40000 | BB38: 8 | BC38: 2026
A39: 32 | B39: LEP080 | D39: Phạm Hùng Cường | E39: Production | F39: Riveting Line Operator | G39: 17/10/2025 | AN39: =COUNTIF(H39:AL39,"W")+COUNTIF(H39:AL39,"W/2")*0.5+COUNTIF(H39:AL39,"BT")+COUNTIF(H39:AL39,"N") -> 0 | AO39: =COUNTIF(H39:AL39,"AL") -> 0 | AP39: =COUNTIF(H39:AL39,"UL") -> 0 | AQ39: =COUNTIF(H39:AL39,"PH") -> 0 | AR39: =COUNTIF(H39:AL39,"SL") -> 0 | AS39: =COUNTIF(H39:AL39,"PL") -> 0 | BA39: -40000 | BB39: 8 | BC39: 2026
A40: 33 | B40: LEP091 | D40: Trần Văn Lựa | E40: Production | F40: Riveting Line Operator | G40: 22/10/2025 | Y40: 2 | AE40: 2 | AN40: =COUNTIF(H40:AL40,"W")+COUNTIF(H40:AL40,"W/2")*0.5+COUNTIF(H40:AL40,"BT")+COUNTIF(H40:AL40,"N") -> 0 | AO40: =COUNTIF(H40:AL40,"AL") -> 0 | AP40: =COUNTIF(H40:AL40,"UL") -> 0 | AQ40: =COUNTIF(H40:AL40,"PH") -> 0 | AR40: =COUNTIF(H40:AL40,"SL") -> 0 | AS40: =COUNTIF(H40:AL40,"PL") -> 0 | BA40: -40000 | BB40: 8 | BC40: 2026
A41: 34 | B41: LEP104 | D41: Nguyễn Quang Linh | E41: Production | F41: Riveting Line Operator | G41: 29/10/2025 | AN41: =COUNTIF(H41:AL41,"W")+COUNTIF(H41:AL41,"W/2")*0.5+COUNTIF(H41:AL41,"BT")+COUNTIF(H41:AL41,"N") -> 0 | AO41: =COUNTIF(H41:AL41,"AL") -> 0 | AP41: =COUNTIF(H41:AL41,"UL") -> 0 | AQ41: =COUNTIF(H41:AL41,"PH") -> 0 | AR41: =COUNTIF(H41:AL41,"SL") -> 0 | AS41: =COUNTIF(H41:AL41,"PL") -> 0 | BA41: -40000 | BB41: 8 | BC41: 2026
A42: 35 | B42: LEP109 | D42: Nguyễn Hữu Đức | E42: Production | F42: Riveting Line Operator | G42: 07/11/2025 | AN42: =COUNTIF(H42:AL42,"W")+COUNTIF(H42:AL42,"W/2")*0.5+COUNTIF(H42:AL42,"BT")+COUNTIF(H42:AL42,"N") -> 0 | AO42: =COUNTIF(H42:AL42,"AL") -> 0 | AP42: =COUNTIF(H42:AL42,"UL") -> 0 | AQ42: =COUNTIF(H42:AL42,"PH") -> 0 | AR42: =COUNTIF(H42:AL42,"SL") -> 0 | AS42: =COUNTIF(H42:AL42,"PL") -> 0 | BA42: -40000 | BB42: 8 | BC42: 2026
A43: 36 | B43: LEP113 | D43: Phan Thị Kim Anh | E43: Production | F43: Production Operator | G43: 18/11/2025 | P43: 2 | Q43: 2 | S43: 2 | V43: 2 | AN43: =COUNTIF(H43:AL43,"W")+COUNTIF(H43:AL43,"W/2")*0.5+COUNTIF(H43:AL43,"BT")+COUNTIF(H43:AL43,"N") -> 0 | AO43: =COUNTIF(H43:AL43,"AL") -> 0 | AP43: =COUNTIF(H43:AL43,"UL") -> 0 | AQ43: =COUNTIF(H43:AL43,"PH") -> 0 | AR43: =COUNTIF(H43:AL43,"SL") -> 0 | AS43: =COUNTIF(H43:AL43,"PL") -> 0 | BA43: -40000 | BB43: 8 | BC43: 2026
...

Sheet Sheet1
A1: stt | B1: MSNV | C1: MS | D1: Họ tên | E1: Bộ phận | F1: Chức vụ | G1: Ngày vào làm | H1: Mã số phòng ban
A2: 1 | B2: LEP001 | C2: 1013789 | D2: Hồ Mỹ Phương | E2: Finance | F2: Finance & Accounting Manager | G2: 28/04/2025 | H2: LEP00146254
A3: 2 | B3: LEP004 | C3: 1014096 | D3: Lê Thành Hưng | E3: EHS | F3: EHS Engineer | G3: 09/06/2025 | H3: LEP00446254
A4: 3 | B4: LEP005 | D4: Tô Văn Thiện | E4: Sales | F4: Sales Manager for S.E.A. | G4: 1/7/2025 | H4: LEP00546254
A5: 4 | B5: LEP007 | C5: 1014338 | D5: Phan Thị Hải Âu | E5: Finance | F5: Accountant | G5: 14/7/2025 | H5: LEP00746254
A6: 5 | B6: LEP009 | C6: 1014359 | D6: Nguyễn Đăng Khoa | E6: Logistics | F6: Logistic Supervisor | G6: 21/7/2025 | H6: LEP00946254
A7: 6 | B7: LEP010 | D7: Trịnh Đình Tâm | E7: WH | F7: Riveting Forklift Driver | G7: 4/8/2025 | H7: LEP01046254
A8: 7 | B8: LEP011 | D8: Phạm Thanh Hiệp | E8: Logistics | F8: Customer Service Representative | G8: 4/8/2025 | H8: LEP01146254
A9: 8 | B9: LEP014 | D9: Phạm Hoàng Dinh | E9: Production | F9: Riveting Team leader | G9: 12/8/2025 | H9: LEP01446254
A10: 9 | B10: LEP018 | D10: Thạch Bạch Tra | E10: WH | F10: Warehouse Forklift Driver | G10: 18/8/2025 | H10: LEP01846254
A11: 10 | B11: LEP022 | D11: Sử Hữu Trí | E11: Production | F11: Riveting Line Operator | G11: 18/8/2025 | H11: LEP02246254
A12: 11 | B12: LEP023 | D12: Phạm Thị Ánh Hồng | E12: Logistics | F12: Customer Service Representative | G12: 20/8/2025 | H12: LEP02346254
A13: 12 | B13: LEP026 | D13: Nguyễn Bá Trinh | E13: WH | F13: WH Operator | G13: 21/8/2025 | H13: LEP02646254
A14: 13 | B14: LEP027 | D14: Nguyễn Vũ Nguyệt Anh | E14: QC | F14: QC Inspector | G14: 25/8/2025 | H14: LEP02746254
A15: 14 | B15: LEP028 | D15: Mã Hén Chiêu | E15: WH | F15: WH Staff | G15: 26/8/2025 | H15: LEP02846254
A16: 15 | B16: LEP029 | D16: Nguyễn Phương Nam | E16: WH | F16: WH Forklift Driver | G16: 26/8/2025 | H16: LEP02946254
A17: 16 | B17: LEP031 | D17: Dương Tấn Thanh | E17: WH | F17: WH Operator | G17: 29/8/2025 | H17: LEP03146254
A18: 17 | B18: LEP036 | D18: Hà Văn Sáng | E18: WH | F18: WH Forklift Driver | G18: 8/9/2025 | H18: LEP03646254
... A103: 102 | B103: LEP336 | D103: Đỗ Lê Nguyên | E103: Production | F103: Production Operator | G103: 21/07/2026 | H103: LEP33646254

Sheet Working time
I1: {=I:X} -> 0
F2: BẢNG CHẤM CÔNG THÁNG 08/ WORKING TIME TABLE AUGUST
C4: Employees under Bau Bang factory's payroll | D4: N: Làm việc ca đêm | E4: AL: Nghỉ phép năm | G4: UL: Nghỉ không lương
A5: No./ STT | B5: Employee ID / Mã nhân viên | C5: Employee ID / Mã nhân viên | D5: Name / Tên nhân viên | E5: Dept/ Bộ phận | F5: Position/ Chức vụ | G5: Start Date Ngày bắt đầu làm việc | I5: 46224 | J5: 46225 | K5: 46226 | L5: 46227 | M5: 46228 | N5: 46229 | O5: 46230 | P5: 46231 | Q5: 46232 | R5: 46233 | S5: 46234 | T5: 46235 | U5: 46236 | V5: 46237 | W5: 46238 | X5: 46239 | Y5: 46240 | Z5: 46241 | AA5: 46242 | AB5: 46243 | AC5: 46244 | AD5: 46245 | AE5: 46246 | AF5: 46247 | AG5: 46248 | AH5: 46249 | AI5: 46250 | AJ5: 46251 | AK5: 46252 | AL5: 46253 | AM5: 46254 | AN5: Total Standard WD/ Tổng số ngày công chuẩn trong tháng | AO5: Total WD / Tồng số ngày làm việc thực tế | AP5: Total AL / Tồng số ngày nghỉ phép năm | AQ5: Total UL/ Tồng số ngày nghỉ không lương | AR5: Total PH/ Tồng số ngày nghỉ lễ | AS5: Total SL/ Tồng số ngày nghỉ ốm | AT5: Total PL/ Nghỉ hưởng lương theo luật như cha mẹ mất, kết hôn | AU5: Số ngày làm việc ban đêm / Số ngày làm việc ban đêm | AV5: Early leaving going late / Đi trễ về sớm | AW5: Performance Bonus/Tiền thưởng năng suất | AX5: Performance Bonus Allowance/ Tiền chuyên cần | AY5: Hazardous Allowance/ Tiền độc hại | AZ5: Firefighting Allowance / Tiền trợ cấp PCCC | BA5: Other fees / Các chi phí khác trong tháng | BB5: Trade Union fee / Trừ tiền đoàn phí | BC5: Month/ Tháng | BD5: Year/ Năm | BE5: Remarks/ Ghi chú | BF5: Employee ID / Mã nhân viên
I6: Tue | J6: Wed | K6: Thu | L6: Fri | M6: Sat | N6: Sun | O6: Mon | P6: Tue | Q6: Wed | R6: Thu | S6: Fri | T6: Sat | U6: Sun | V6: Mon | W6: Tue | X6: Wed | Y6: Thu | Z6: Fri | AA6: Sat | AB6: Sun | AC6: Mon | AD6: Tue | AE6: Wed | AF6: Thu | AG6: Fri | AH6: Sat | AI6: Sun | AJ6: Mon | AK6: Tue | AL6: Wed | AM6: Thu
I7: T3 | J7: T4 | K7: T5 | L7: T6 | M7: T7 | N7: CN | O7: T2 | P7: T3 | Q7: T4 | R7: T5 | S7: T6 | T7: T7 | U7: CN | V7: T2 | W7: T3 | X7: T4 | Y7: T5 | Z7: T6 | AA7: T7 | AB7: CN | AC7: T2 | AD7: T3 | AE7: T4 | AF7: T5 | AG7: T6 | AH7: T7 | AI7: CN | AJ7: T2 | AK7: T3 | AL7: T4 | AM7: T5 | BF7: Tiền năng suất từ anh Khoa
A8: 1 | B8: LEP001 | C8: 1013789 | D8: Hồ Mỹ Phương | E8: Finance | F8: Finance & Accounting Manager | G8: 28/04/2025 | H8: =B8&$AM$5 -> LEP00146254 | I8: W | J8: W | K8: W | L8: W | O8: W | P8: W | Q8: W | R8: W | S8: W | V8: W | W8: W | X8: W | Y8: W | Z8: W | AC8: W | AD8: W | AE8: W | AF8: W | AG8: W | AJ8: W | AK8: W | AL8: W | AM8: W | AN8: 23 | AO8: =COUNTIF(I8:AM8,"W")+COUNTIF(I8:AM8,"W/2 AL/2")*0.5+COUNTIF(I8:AM8,"BT")+COUNTIF(I8:AM8,"N")++COUNTIF(I8:AM8,"W/2 UL/2")*0.5 -> 23 | AP8: =COUNTIF(I8:AM8,"AL")+COUNTIF(I8:AM8,"W/2 AL/2")*0.5+COUNTIF(I8:AM8,"AL/2 UL/2")*0.5 -> 0 | AQ8: =COUNTIF(I8:AM8,"UL")+COUNTIF(I8:AM8,"W/2 UL/2")*0.5+COUNTIF(I8:AM8,"AL/2 UL/2")*0.5 -> 0 | AR8: =COUNTIF(I8:AM8,"PH") -> 0 | AS8: =COUNTIF(I8:AM8,"SL") -> 0 | AT8: =COUNTIF(I8:AM8,"PL") -> 0 | BB8: -40000 | BC8: 8 | BD8: 2026 | BF8: 0
A9: 2 | B9: LEP004 | C9: 1014096 | D9: Lê Thành Hưng | E9: EHS | F9: EHS Engineer | G9: 09/06/2025 | H9: =B9&$AM$5 -> LEP00446254 | I9: W | J9: W | K9: W | L9: W | O9: W | P9: W | Q9: BT | R9: W | S9: W | V9: W | W9: W | X9: W | Y9: W | Z9: W | AC9: BT | AD9: W | AE9: W | AF9: W | AG9: W | AJ9: W | AK9: W | AL9: W | AM9: W | AN9: 23 | AO9: =COUNTIF(I9:AM9,"W")+COUNTIF(I9:AM9,"W/2 AL/2")*0.5+COUNTIF(I9:AM9,"BT")+COUNTIF(I9:AM9,"N")++COUNTIF(I9:AM9,"W/2 UL/2")*0.5 -> 23 | AP9: =COUNTIF(I9:AM9,"AL")+COUNTIF(I9:AM9,"W/2 AL/2")*0.5+COUNTIF(I9:AM9,"AL/2 UL/2")*0.5 -> 0 | AQ9: =COUNTIF(I9:AM9,"UL")+COUNTIF(I9:AM9,"W/2 UL/2")*0.5+COUNTIF(I9:AM9,"AL/2 UL/2")*0.5 -> 0 | AR9: =COUNTIF(I9:AM9,"PH") -> 0 | AS9: =COUNTIF(I9:AM9,"SL") -> 0 | AT9: =COUNTIF(I9:AM9,"PL") -> 0 | AZ9: 992000 | BB9: -40000 | BC9: 8 | BD9: 2026 | BF9: 0
A10: 3 | B10: LEP005 | D10: Tô Văn Thiện | E10: Sales | F10: Sales Manager for S.E.A. | G10: 1/7/2025 | H10: =B10&$AM$5 -> LEP00546254 | I10: W | J10: W | K10: W | L10: W | O10: W | P10: W | Q10: W | R10: W | S10: W | V10: W | W10: W | X10: W | Y10: W | Z10: W | AC10: W | AD10: W | AE10: W | AF10: W | AG10: W | AJ10: W | AK10: W | AL10: W | AM10: W | AN10: 23 | AO10: =COUNTIF(I10:AM10,"W")+COUNTIF(I10:AM10,"W/2 AL/2")*0.5+COUNTIF(I10:AM10,"BT")+COUNTIF(I10:AM10,"N")++COUNTIF(I10:AM10,"W/2 UL/2")*0.5 -> 23 | AP10: =COUNTIF(I10:AM10,"AL")+COUNTIF(I10:AM10,"W/2 AL/2")*0.5+COUNTIF(I10:AM10,"AL/2 UL/2")*0.5 -> 0 | AQ10: =COUNTIF(I10:AM10,"UL")+COUNTIF(I10:AM10,"W/2 UL/2")*0.5+COUNTIF(I10:AM10,"AL/2 UL/2")*0.5 -> 0 | AR10: =COUNTIF(I10:AM10,"PH") -> 0 | AS10: =COUNTIF(I10:AM10,"SL") -> 0 | AT10: =COUNTIF(I10:AM10,"PL") -> 0 | BB10: -40000 | BC10: 8 | BD10: 2026 | BF10: 0
A11: 4 | B11: LEP007 | C11: 1014338 | D11: Phan Thị Hải Âu | E11: Finance | F11: Accountant | G11: 14/7/2025 | H11: =B11&$AM$5 -> LEP00746254 | I11: W | J11: W | K11: W | L11: W | O11: W | P11: W | Q11: W | R11: W | S11: W | V11: W | W11: W | X11: W | Y11: W | Z11: W | AC11: W | AD11: W | AE11: W | AF11: W | AG11: W | AJ11: W | AK11: W | AL11: W | AM11: W | AN11: 23 | AO11: =COUNTIF(I11:AM11,"W")+COUNTIF(I11:AM11,"W/2 AL/2")*0.5+COUNTIF(I11:AM11,"BT")+COUNTIF(I11:AM11,"N")++COUNTIF(I11:AM11,"W/2 UL/2")*0.5 -> 23 | AP11: =COUNTIF(I11:AM11,"AL")+COUNTIF(I11:AM11,"W/2 AL/2")*0.5+COUNTIF(I11:AM11,"AL/2 UL/2")*0.5 -> 0 | AQ11: =COUNTIF(I11:AM11,"UL")+COUNTIF(I11:AM11,"W/2 UL/2")*0.5+COUNTIF(I11:AM11,"AL/2 UL/2")*0.5 -> 0 | AR11: =COUNTIF(I11:AM11,"PH") -> 0 | AS11: =COUNTIF(I11:AM11,"SL") -> 0 | AT11: =COUNTIF(I11:AM11,"PL") -> 0 | BB11: -40000 | BC11: 8 | BD11: 2026 | BF11: 0
A12: 5 | B12: LEP009 | C12: 1014359 | D12: Nguyễn Đăng Khoa | E12: Logistics | F12: Logistic Supervisor | G12: 21/7/2025 | H12: =B12&$AM$5 -> LEP00946254 | I12: W | J12: W | K12: W | L12: W | O12: W | P12: W | Q12: W | R12: W | S12: W | V12: W | W12: W | X12: W | Y12: W | Z12: AL | AC12: W | AD12: W | AE12: W | AF12: W | AG12: W | AJ12: W | AK12: W | AL12: W | AM12: W | AN12: 23 | AO12: =COUNTIF(I12:AM12,"W")+COUNTIF(I12:AM12,"W/2 AL/2")*0.5+COUNTIF(I12:AM12,"BT")+COUNTIF(I12:AM12,"N")++COUNTIF(I12:AM12,"W/2 UL/2")*0.5 -> 22 | AP12: =COUNTIF(I12:AM12,"AL")+COUNTIF(I12:AM12,"W/2 AL/2")*0.5+COUNTIF(I12:AM12,"AL/2 UL/2")*0.5 -> 1 | AQ12: =COUNTIF(I12:AM12,"UL")+COUNTIF(I12:AM12,"W/2 UL/2")*0.5+COUNTIF(I12:AM12,"AL/2 UL/2")*0.5 -> 0 | AR12: =COUNTIF(I12:AM12,"PH") -> 0 | AS12: =COUNTIF(I12:AM12,"SL") -> 0 | AT12: =COUNTIF(I12:AM12,"PL") -> 0 | BB12: -40000 | BC12: 8 | BD12: 2026 | BF12: 0
A13: 6 | B13: LEP010 | D13: Trịnh Đình Tâm | E13: WH | F13: Riveting Forklift Driver | G13: 4/8/2025 | H13: =B13&$AM$5 -> LEP01046254 | I13: W | J13: W | K13: W | L13: W | M13: W | O13: W | P13: W | Q13: W | R13: UL | S13: W | T13: W | V13: W | W13: W | X13: W | Y13: W | Z13: W | AA13: W/2 AL/2 | AC13: W | AD13: W | AE13: W | AF13: W | AG13: W | AH13: W | AJ13: W | AK13: W | AL13: UL | AM13: W | AN13: 27 | AO13: =COUNTIF(I13:AM13,"W")+COUNTIF(I13:AM13,"W/2 AL/2")*0.5+COUNTIF(I13:AM13,"BT")+COUNTIF(I13:AM13,"N")++COUNTIF(I13:AM13,"W/2 UL/2")*0.5 -> 24.5 | AP13: =COUNTIF(I13:AM13,"AL")+COUNTIF(I13:AM13,"W/2 AL/2")*0.5+COUNTIF(I13:AM13,"AL/2 UL/2")*0.5 -> 0.5 | AQ13: =COUNTIF(I13:AM13,"UL")+COUNTIF(I13:AM13,"W/2 UL/2")*0.5+COUNTIF(I13:AM13,"AL/2 UL/2")*0.5 -> 2 | AR13: =COUNTIF(I13:AM13,"PH") -> 0 | AS13: =COUNTIF(I13:AM13,"SL") -> 0 | AT13: =COUNTIF(I13:AM13,"PL") -> 0 | AW13: =(AO13+AP13)*BF13/AN13 -> 925925.93 | AX13: =500000*(1-IF(COUNTIF(J13:AM13,"UL")>=2,IF(COUNTIF(J13:AM13,"UL")>=3,1,0.5),0)) -> 250000 | BB13: -40000 | BC13: 8 | BD13: 2026 | BF13: 1000000
A14: 7 | B14: LEP011 | D14: Phạm Thanh Hiệp | E14: Logistics | F14: Customer Service Representative | G14: 4/8/2025 | H14: =B14&$AM$5 -> LEP01146254 | I14: W | J14: W | K14: W | L14: W | O14: W | P14: W | Q14: W | R14: W | S14: W | T14: 0 | V14: 0 | W14: RESIGNED | X14: 0 | Y14: 0 | Z14: 0 | AA14: 0 | AC14: 0 | AD14: 0 | AE14: 0 | AF14: 0 | AG14: 0 | AJ14: 0 | AK14: 0 | AL14: 0 | AM14: 0 | AN14: 23 | AO14: =COUNTIF(I14:AM14,"W")+COUNTIF(I14:AM14,"W/2 AL/2")*0.5+COUNTIF(I14:AM14,"BT")+COUNTIF(I14:AM14,"N")++COUNTIF(I14:AM14,"W/2 UL/2")*0.5 -> 9 | AP14: =COUNTIF(I14:AM14,"AL")+COUNTIF(I14:AM14,"W/2 AL/2")*0.5+COUNTIF(I14:AM14,"AL/2 UL/2")*0.5 -> 0 | AQ14: =COUNTIF(I14:AM14,"UL")+COUNTIF(I14:AM14,"W/2 UL/2")*0.5+COUNTIF(I14:AM14,"AL/2 UL/2")*0.5 -> 0 | AR14: =COUNTIF(I14:AM14,"PH") -> 0 | AS14: =COUNTIF(I14:AM14,"SL") -> 0 | AT14: =COUNTIF(I14:AM14,"PL") -> 0 | BB14: -40000 | BC14: 8 | BD14: 2026 | BE14: NghỈ việc do hết hợp đồng, còn dư 4 ngày phép | BF14: 0
A15: 8 | B15: LEP014 | D15: Phạm Hoàng Dinh | E15: Production | F15: Riveting Team leader | G15: 12/8/2025 | H15: =B15&$AM$5 -> LEP01446254 | I15: W | J15: W | K15: W | L15: W | M15: W | O15: W | P15: W | Q15: W | R15: W | S15: W | T15: W | V15: W | W15: W | X15: W | Y15: RESIGNED | Z15: 0 | AA15: 0 | AC15: 0 | AD15: 0 | AE15: 0 | AF15: 0 | AG15: 0 | AJ15: 0 | AK15: 0 | AL15: 0 | AM15: 0 | AN15: 27 | AO15: =COUNTIF(I15:AM15,"W")+COUNTIF(I15:AM15,"W/2 AL/2")*0.5+COUNTIF(I15:AM15,"BT")+COUNTIF(I15:AM15,"N")++COUNTIF(I15:AM15,"W/2 UL/2")*0.5 -> 14 | AP15: =COUNTIF(I15:AM15,"AL")+COUNTIF(I15:AM15,"W/2 AL/2")*0.5+COUNTIF(I15:AM15,"AL/2 UL/2")*0.5 -> 0 | AQ15: =COUNTIF(I15:AM15,"UL")+COUNTIF(I15:AM15,"W/2 UL/2")*0.5+COUNTIF(I15:AM15,"AL/2 UL/2")*0.5 -> 0 | AR15: =COUNTIF(I15:AM15,"PH") -> 0 | AS15: =COUNTIF(I15:AM15,"SL") -> 0 | AT15: =COUNTIF(I15:AM15,"PL") -> 0 | AW15: =(AO15+AP15)*BF15/AN15 -> 0 | AX15: =500000*(1-IF(COUNTIF(J15:AM15,"UL")>=2,IF(COUNTIF(J15:AM15,"UL")>=3,1,0.5),0)) -> 500000 | BB15: -40000 | BC15: 8 | BD15: 2026 | BF15: 0
A16: 9 | B16: LEP018 | D16: Thạch Bạch Tra | E16: WH | F16: Warehouse Forklift Driver | G16: 18/8/2025 | H16: =B16&$AM$5 -> LEP01846254 | I16: W | J16: W | K16: W | L16: W | M16: W | O16: W | P16: W | Q16: W | R16: W | S16: AL | T16: W | V16: W | W16: W | X16: W | Y16: W | Z16: W | AA16: W | AC16: W | AD16: W | AE16: W | AF16: W | AG16: W | AH16: W | AJ16: W | AK16: W | AL16: W | AM16: W | AN16: 27 | AO16: =COUNTIF(I16:AM16,"W")+COUNTIF(I16:AM16,"W/2 AL/2")*0.5+COUNTIF(I16:AM16,"BT")+COUNTIF(I16:AM16,"N")++COUNTIF(I16:AM16,"W/2 UL/2")*0.5 -> 26 | AP16: =COUNTIF(I16:AM16,"AL")+COUNTIF(I16:AM16,"W/2 AL/2")*0.5+COUNTIF(I16:AM16,"AL/2 UL/2")*0.5 -> 1 | AQ16: =COUNTIF(I16:AM16,"UL")+COUNTIF(I16:AM16,"W/2 UL/2")*0.5+COUNTIF(I16:AM16,"AL/2 UL/2")*0.5 -> 0 | AR16: =COUNTIF(I16:AM16,"PH") -> 0 | AS16: =COUNTIF(I16:AM16,"SL") -> 0 | AT16: =COUNTIF(I16:AM16,"PL") -> 0 | AW16: =(AO16+AP16)*BF16/AN16 -> 1000000 | AX16: =500000*(1-IF(COUNTIF(J16:AM16,"UL")>=2,IF(COUNTIF(J16:AM16,"UL")>=3,1,0.5),0)) -> 500000 | BB16: -40000 | BC16: 8 | BD16: 2026 | BF16: 1000000
A17: 10 | B17: LEP022 | D17: Sử Hữu Trí | E17: Production | F17: Riveting Line Operator | G17: 18/8/2025 | H17: =B17&$AM$5 -> LEP02246254 | I17: W | J17: W | K17: W | L17: W | M17: W | O17: W | P17: W | Q17: W | R17: W | S17: W | T17: W | V17: W | W17: W | X17: W | Y17: W | Z17: W | AA17: W | AC17: W | AD17: W | AE17: W | AF17: W | AG17: W | AH17: W | AJ17: W | AK17: W | AL17: W | AM17: W | AN17: 27 | AO17: =COUNTIF(I17:AM17,"W")+COUNTIF(I17:AM17,"W/2 AL/2")*0.5+COUNTIF(I17:AM17,"BT")+COUNTIF(I17:AM17,"N")++COUNTIF(I17:AM17,"W/2 UL/2")*0.5 -> 27 | AP17: =COUNTIF(I17:AM17,"AL")+COUNTIF(I17:AM17,"W/2 AL/2")*0.5+COUNTIF(I17:AM17,"AL/2 UL/2")*0.5 -> 0 | AQ17: =COUNTIF(I17:AM17,"UL")+COUNTIF(I17:AM17,"W/2 UL/2")*0.5+COUNTIF(I17:AM17,"AL/2 UL/2")*0.5 -> 0 | AR17: =COUNTIF(I17:AM17,"PH") -> 0 | AS17: =COUNTIF(I17:AM17,"SL") -> 0 | AT17: =COUNTIF(I17:AM17,"PL") -> 0 | AW17: =(AO17+AP17)*BF17/AN17 -> 1064259 | AX17: =500000*(1-IF(COUNTIF(J17:AM17,"UL")>=2,IF(COUNTIF(J17:AM17,"UL")>=3,1,0.5),0)) -> 500000 | BB17: -40000 | BC17: 8 | BD17: 2026 | BF17: 1064259
A18: 11 | B18: LEP023 | D18: Phạm Thị Ánh Hồng | E18: Logistics | F18: Customer Service Representative | G18: 20/8/2025 | H18: =B18&$AM$5 -> LEP02346254 | I18: W | J18: W | K18: W | L18: W | M18: 0 | O18: W | P18: W | Q18: W | R18: W | S18: W | T18: 0 | V18: W | W18: W | X18: W | Y18: W | Z18: W | AC18: W | AD18: W | AE18: W | AF18: W | AG18: W | AJ18: W | AK18: W | AL18: W | AM18: W | AN18: 23 | AO18: =COUNTIF(I18:AM18,"W")+COUNTIF(I18:AM18,"W/2 AL/2")*0.5+COUNTIF(I18:AM18,"BT")+COUNTIF(I18:AM18,"N")++COUNTIF(I18:AM18,"W/2 UL/2")*0.5 -> 23 | AP18: =COUNTIF(I18:AM18,"AL")+COUNTIF(I18:AM18,"W/2 AL/2")*0.5+COUNTIF(I18:AM18,"AL/2 UL/2")*0.5 -> 0 | AQ18: =COUNTIF(I18:AM18,"UL")+COUNTIF(I18:AM18,"W/2 UL/2")*0.5+COUNTIF(I18:AM18,"AL/2 UL/2")*0.5 -> 0 | AR18: =COUNTIF(I18:AM18,"PH") -> 0 | AS18: =COUNTIF(I18:AM18,"SL") -> 0 | AT18: =COUNTIF(I18:AM18,"PL") -> 0 | AW18: =(AO18+AP18)*BF18/AN18 -> 0 | BB18: -40000 | BC18: 8 | BD18: 2026 | BF18: 0
A19: 12 | B19: LEP026 | D19: Nguyễn Bá Trinh | E19: WH | F19: WH Operator | H19: =B19&$AM$5 -> LEP02646254 | I19: W | J19: W | K19: W | L19: W | M19: W | O19: W | P19: W | Q19: W | R19: W | S19: W | T19: W | V19: W | W19: W | X19: W | Y19: W | Z19: W | AA19: W | AC19: W | AD19: W | AE19: W | AF19: W | AG19: W | AH19: W | AJ19: W | AK19: W | AL19: W | AM19: W | AN19: 27 | AO19: =COUNTIF(I19:AM19,"W")+COUNTIF(I19:AM19,"W/2 AL/2")*0.5+COUNTIF(I19:AM19,"BT")+COUNTIF(I19:AM19,"N")++COUNTIF(I19:AM19,"W/2 UL/2")*0.5 -> 27 | AP19: =COUNTIF(I19:AM19,"AL")+COUNTIF(I19:AM19,"W/2 AL/2")*0.5+COUNTIF(I19:AM19,"AL/2 UL/2")*0.5 -> 0 | AQ19: =COUNTIF(I19:AM19,"UL")+COUNTIF(I19:AM19,"W/2 UL/2")*0.5+COUNTIF(I19:AM19,"AL/2 UL/2")*0.5 -> 0 | AR19: =COUNTIF(I19:AM19,"PH") -> 0 | AS19: =COUNTIF(I19:AM19,"SL") -> 0 | AT19: =COUNTIF(I19:AM19,"PL") -> 0 | AW19: =(AO19+AP19)*BF19/AN19 -> 1000000 | AX19: =500000*(1-IF(COUNTIF(J19:AM19,"UL")>=2,IF(COUNTIF(J19:AM19,"UL")>=3,1,0.5),0)) -> 500000 | BB19: -40000 | BC19: 8 | BD19: 2026 | BF19: 1000000
A20: 13 | B20: LEP027 | D20: Nguyễn Vũ Nguyệt Anh | E20: QC | F20: QC Inspector | G20: 25/8/2025 | H20: =B20&$AM$5 -> LEP02746254 | I20: SL | J20: SL | K20: SL | L20: SL | M20: AL | O20: W | P20: W | Q20: W | R20: W | S20: W | T20: W | V20: W | W20: W | X20: W | Y20: W | Z20: W | AA20: W | AC20: W | AD20: W | AE20: W | AF20: W | AG20: W | AH20: W | AJ20: W | AK20: W | AL20: W | AM20: W | AN20: 27 | AO20: =COUNTIF(I20:AM20,"W")+COUNTIF(I20:AM20,"W/2 AL/2")*0.5+COUNTIF(I20:AM20,"BT")+COUNTIF(I20:AM20,"N")++COUNTIF(I20:AM20,"W/2 UL/2")*0.5 -> 22 | AP20: =COUNTIF(I20:AM20,"AL")+COUNTIF(I20:AM20,"W/2 AL/2")*0.5+COUNTIF(I20:AM20,"AL/2 UL/2")*0.5 -> 1 | AQ20: =COUNTIF(I20:AM20,"UL")+COUNTIF(I20:AM20,"W/2 UL/2")*0.5+COUNTIF(I20:AM20,"AL/2 UL/2")*0.5 -> 0 | AR20: =COUNTIF(I20:AM20,"PH") -> 0 | AS20: =COUNTIF(I20:AM20,"SL") -> 4 | AT20: =COUNTIF(I20:AM20,"PL") -> 0 | AW20: =(AO20+AP20)*BF20/AN20 -> 851851.85 | AX20: 500000 | BB20: -40000 | BC20: 8 | BD20: 2026 | BF20: 1000000
A21: 14 | B21: LEP028 | D21: Mã Hén Chiêu | E21: WH | F21: WH Staff | G21: 26/8/2025 | H21: =B21&$AM$5 -> LEP02846254 | I21: W | J21: W | K21: W | L21: W | M21: W | O21: W | P21: W | Q21: W | R21: W | S21: W | T21: W | V21: UL | W21: W | X21: W | Y21: W | Z21: W | AA21: W | AC21: W | AD21: W | AE21: W | AF21: W | AG21: W | AH21: W | AJ21: W | AK21: W | AL21: W | AM21: W | AN21: 27 | AO21: =COUNTIF(I21:AM21,"W")+COUNTIF(I21:AM21,"W/2 AL/2")*0.5+COUNTIF(I21:AM21,"BT")+COUNTIF(I21:AM21,"N")++COUNTIF(I21:AM21,"W/2 UL/2")*0.5 -> 26 | AP21: =COUNTIF(I21:AM21,"AL")+COUNTIF(I21:AM21,"W/2 AL/2")*0.5+COUNTIF(I21:AM21,"AL/2 UL/2")*0.5 -> 0 | AQ21: =COUNTIF(I21:AM21,"UL")+COUNTIF(I21:AM21,"W/2 UL/2")*0.5+COUNTIF(I21:AM21,"AL/2 UL/2")*0.5 -> 1 | AR21: =COUNTIF(I21:AM21,"PH") -> 0 | AS21: =COUNTIF(I21:AM21,"SL") -> 0 | AT21: =COUNTIF(I21:AM21,"PL") -> 0 | AW21: =(AO21+AP21)*BF21/AN21 -> 962962.96 | AX21: =500000*(1-IF(COUNTIF(J21:AM21,"UL")>=2,IF(COUNTIF(J21:AM21,"UL")>=3,1,0.5),0)) -> 500000 | BB21: -40000 | BC21: 8 | BD21: 2026 | BF21: 1000000
A22: 15 | B22: LEP029 | D22: Nguyễn Phương Nam | E22: WH | F22: WH Forklift Driver | G22: 26/8/2025 | H22: =B22&$AM$5 -> LEP02946254 | I22: W | J22: W | K22: W | L22: W | M22: W | O22: W | P22: W | Q22: W | R22: W | S22: W | T22: W | V22: W | W22: W | X22: W | Y22: W | Z22: AL | AA22: W | AC22: W | AD22: W | AE22: W | AF22: UL | AG22: W | AH22: W | AJ22: W | AK22: W | AL22: W | AM22: W | AN22: 27 | AO22: =COUNTIF(I22:AM22,"W")+COUNTIF(I22:AM22,"W/2 AL/2")*0.5+COUNTIF(I22:AM22,"BT")+COUNTIF(I22:AM22,"N")++COUNTIF(I22:AM22,"W/2 UL/2")*0.5 -> 25 | AP22: =COUNTIF(I22:AM22,"AL")+COUNTIF(I22:AM22,"W/2 AL/2")*0.5+COUNTIF(I22:AM22,"AL/2 UL/2")*0.5 -> 1 | AQ22: =COUNTIF(I22:AM22,"UL")+COUNTIF(I22:AM22,"W/2 UL/2")*0.5+COUNTIF(I22:AM22,"AL/2 UL/2")*0.5 -> 1 | AR22: =COUNTIF(I22:AM22,"PH") -> 0 | AS22: =COUNTIF(I22:AM22,"SL") -> 0 | AT22: =COUNTIF(I22:AM22,"PL") -> 0 | AW22: =(AO22+AP22)*BF22/AN22 -> 962962.96 | AX22: =500000*(1-IF(COUNTIF(J22:AM22,"UL")>=2,IF(COUNTIF(J22:AM22,"UL")>=3,1,0.5),0)) -> 500000 | BB22: -40000 | BC22: 8 | BD22: 2026 | BF22: 1000000
A23: 16 | B23: LEP031 | D23: Dương Tấn Thanh | E23: WH | F23: WH Operator | G23: 29/8/2025 | H23: =B23&$AM$5 -> LEP03146254 | I23: W | J23: W | K23: W | L23: W | M23: W | O23: W | P23: W | Q23: W | R23: W | S23: W | T23: W | V23: W | W23: W | X23: W | Y23: W | Z23: W | AA23: W | AC23: W | AD23: AL | AE23: W | AF23: W | AG23: W | AH23: W | AJ23: W | AK23: W | AL23: W | AM23: W | AN23: 27 | AO23: =COUNTIF(I23:AM23,"W")+COUNTIF(I23:AM23,"W/2 AL/2")*0.5+COUNTIF(I23:AM23,"BT")+COUNTIF(I23:AM23,"N")++COUNTIF(I23:AM23,"W/2 UL/2")*0.5 -> 26 | AP23: =COUNTIF(I23:AM23,"AL")+COUNTIF(I23:AM23,"W/2 AL/2")*0.5+COUNTIF(I23:AM23,"AL/2 UL/2")*0.5 -> 1 | AQ23: =COUNTIF(I23:AM23,"UL")+COUNTIF(I23:AM23,"W/2 UL/2")*0.5+COUNTIF(I23:AM23,"AL/2 UL/2")*0.5 -> 0 | AR23: =COUNTIF(I23:AM23,"PH") -> 0 | AS23: =COUNTIF(I23:AM23,"SL") -> 0 | AT23: =COUNTIF(I23:AM23,"PL") -> 0 | AW23: =(AO23+AP23)*BF23/AN23 -> 1000000 | AX23: =500000*(1-IF(COUNTIF(J23:AM23,"UL")>=2,IF(COUNTIF(J23:AM23,"UL")>=3,1,0.5),0)) -> 500000 | BB23: -40000 | BC23: 8 | BD23: 2026 | BF23: 1000000
A24: 17 | B24: LEP036 | D24: Hà Văn Sáng | E24: WH | F24: WH Forklift Driver | G24: 45878 | H24: =B24&$AM$5 -> LEP03646254 | I24: W | J24: W | K24: W | L24: W | M24: W | O24: AL | P24: W | Q24: W | R24: W | S24: W | T24: W | V24: W | W24: W | X24: W | Y24: W | Z24: W | AA24: W | AC24: W | AD24: W | AE24: W | AF24: W | AG24: W | AH24: W | AJ24: AL | AK24: W | AL24: W | AM24: W | AN24: 27 | AO24: =COUNTIF(I24:AM24,"W")+COUNTIF(I24:AM24,"W/2 AL/2")*0.5+COUNTIF(I24:AM24,"BT")+COUNTIF(I24:AM24,"N")++COUNTIF(I24:AM24,"W/2 UL/2")*0.5 -> 25 | AP24: =COUNTIF(I24:AM24,"AL")+COUNTIF(I24:AM24,"W/2 AL/2")*0.5+COUNTIF(I24:AM24,"AL/2 UL/2")*0.5 -> 2 | AQ24: =COUNTIF(I24:AM24,"UL")+COUNTIF(I24:AM24,"W/2 UL/2")*0.5+COUNTIF(I24:AM24,"AL/2 UL/2")*0.5 -> 0 | AR24: =COUNTIF(I24:AM24,"PH") -> 0 | AS24: =COUNTIF(I24:AM24,"SL") -> 0 | AT24: =COUNTIF(I24:AM24,"PL") -> 0 | AW24: =(AO24+AP24)*BF24/AN24 -> 1000000 | AX24: =500000*(1-IF(COUNTIF(J24:AM24,"UL")>=2,IF(COUNTIF(J24:AM24,"UL")>=3,1,0.5),0)) -> 500000 | BB24: -40000 | BC24: 8 | BD24: 2026 | BF24: 1000000
A25: 18 | B25: LEP040 | D25: Dương Văn Thành | E25: Finance | F25: Branch IT Administrator | G25: 15/09/2025 | H25: =B25&$AM$5 -> LEP04046254 | I25: W | J25: W | K25: W | L25: W | O25: W | P25: W | Q25: W | R25: W | S25: AL | V25: W | W25: W | X25: W | Y25: W | Z25: W | AC25: W | AD25: W | AE25: W | AF25: W | AG25: W | AJ25: W | AK25: W | AL25: W | AM25: W | AN25: 23 | AO25: =COUNTIF(I25:AM25,"W")+COUNTIF(I25:AM25,"W/2 AL/2")*0.5+COUNTIF(I25:AM25,"BT")+COUNTIF(I25:AM25,"N")++COUNTIF(I25:AM25,"W/2 UL/2")*0.5 -> 22 | AP25: =COUNTIF(I25:AM25,"AL")+COUNTIF(I25:AM25,"W/2 AL/2")*0.5+COUNTIF(I25:AM25,"AL/2 UL/2")*0.5 -> 1 | AQ25: =COUNTIF(I25:AM25,"UL")+COUNTIF(I25:AM25,"W/2 UL/2")*0.5+COUNTIF(I25:AM25,"AL/2 UL/2")*0.5 -> 0 | AR25: =COUNTIF(I25:AM25,"PH") -> 0 | AS25: =COUNTIF(I25:AM25,"SL") -> 0 | AT25: =COUNTIF(I25:AM25,"PL") -> 0 | AW25: =(AO25+AP25)*BF25/AN25 -> 0 | BB25: -40000 | BC25: 8 | BD25: 2026 | BF25: 0
A26: 19 | B26: LEP045 | D26: Huỳnh Hoài Thương | E26: Production | F26: Riveting Line Operator | G26: 17/09/2025 | H26: =B26&$AM$5 -> LEP04546254 | I26: W | J26: W | K26: UL | L26: W | M26: W | O26: W | P26: W | Q26: W | R26: W | S26: W | T26: W | V26: W | W26: W | X26: AL | Y26: W | Z26: W | AA26: W | AC26: W | AD26: W | AE26: W | AF26: W | AG26: W | AH26: W | AJ26: UL | AK26: W | AL26: W | AM26: W | AN26: 27 | AO26: =COUNTIF(I26:AM26,"W")+COUNTIF(I26:AM26,"W/2 AL/2")*0.5+COUNTIF(I26:AM26,"BT")+COUNTIF(I26:AM26,"N")++COUNTIF(I26:AM26,"W/2 UL/2")*0.5 -> 24 | AP26: =COUNTIF(I26:AM26,"AL")+COUNTIF(I26:AM26,"W/2 AL/2")*0.5+COUNTIF(I26:AM26,"AL/2 UL/2")*0.5 -> 1 | AQ26: =COUNTIF(I26:AM26,"UL")+COUNTIF(I26:AM26,"W/2 UL/2")*0.5+COUNTIF(I26:AM26,"AL/2 UL/2")*0.5 -> 2 | AR26: =COUNTIF(I26:AM26,"PH") -> 0 | AS26: =COUNTIF(I26:AM26,"SL") -> 0 | AT26: =COUNTIF(I26:AM26,"PL") -> 0 | AW26: =(AO26+AP26)*BF26/AN26 -> 985425 | AX26: =500000*(1-IF(COUNTIF(J26:AM26,"UL")>=2,IF(COUNTIF(J26:AM26,"UL")>=3,1,0.5),0)) -> 250000 | BB26: -40000 | BC26: 8 | BD26: 2026 | BF26: 1064259
A27: 20 | B27: LEP048 | D27: Phan Phước Tài | E27: Maintenance (PRO) | F27: Mechanical Maintenance Specialist | G27: 25/09/2025 | H27: =B27&$AM$5 -> LEP04846254 | I27: W/2 AL/2 | J27: AL | K27: W | L27: W | M27: W | O27: W | P27: W | Q27: W | R27: W | S27: W | T27: W | V27: W | W27: W | X27: W | Y27: W | Z27: W | AA27: W | AC27: W | AD27: W | AE27: W | AF27: W | AG27: W | AH27: W | AJ27: W | AK27: W | AL27: W | AM27: W | AN27: 27 | AO27: =COUNTIF(I27:AM27,"W")+COUNTIF(I27:AM27,"W/2 AL/2")*0.5+COUNTIF(I27:AM27,"BT")+COUNTIF(I27:AM27,"N")++COUNTIF(I27:AM27,"W/2 UL/2")*0.5 -> 25.5 | AP27: =COUNTIF(I27:AM27,"AL")+COUNTIF(I27:AM27,"W/2 AL/2")*0.5+COUNTIF(I27:AM27,"AL/2 UL/2")*0.5 -> 1.5 | AQ27: =COUNTIF(I27:AM27,"UL")+COUNTIF(I27:AM27,"W/2 UL/2")*0.5+COUNTIF(I27:AM27,"AL/2 UL/2")*0.5 -> 0 | AR27: =COUNTIF(I27:AM27,"PH") -> 0 | AS27: =COUNTIF(I27:AM27,"SL") -> 0 | AT27: =COUNTIF(I27:AM27,"PL") -> 0 | AW27: =(AO27+AP27)*BF27/AN27 -> 1000000 | AX27: 500000 | AZ27: 992000 | BB27: -40000 | BC27: 8 | BD27: 2026 | BF27: 1000000
A28: 21 | B28: LEP049 | D28: Ngô Viết Đức | E28: Maintenance (PRO) | F28: Electrical Maintenance Specialist | G28: 25/09/2025 | H28: =B28&$AM$5 -> LEP04946254 | I28: W | J28: W | K28: W | L28: W | M28: W | O28: W | P28: W | Q28: W | R28: W | S28: W | T28: W | V28: W | W28: W | X28: W | Y28: W | Z28: W | AA28: W | AC28: W | AD28: W | AE28: W | AF28: W | AG28: W | AH28: W | AJ28: W | AK28: W | AL28: W | AM28: W | AN28: 27 | AO28: =COUNTIF(I28:AM28,"W")+COUNTIF(I28:AM28,"W/2 AL/2")*0.5+COUNTIF(I28:AM28,"BT")+COUNTIF(I28:AM28,"N")++COUNTIF(I28:AM28,"W/2 UL/2")*0.5 -> 27 | AP28: =COUNTIF(I28:AM28,"AL")+COUNTIF(I28:AM28,"W/2 AL/2")*0.5+COUNTIF(I28:AM28,"AL/2 UL/2")*0.5 -> 0 | AQ28: =COUNTIF(I28:AM28,"UL")+COUNTIF(I28:AM28,"W/2 UL/2")*0.5+COUNTIF(I28:AM28,"AL/2 UL/2")*0.5 -> 0 | AR28: =COUNTIF(I28:AM28,"PH") -> 0 | AS28: =COUNTIF(I28:AM28,"SL") -> 0 | AT28: =COUNTIF(I28:AM28,"PL") -> 0 | AW28: =(AO28+AP28)*BF28/AN28 -> 1000000 | AX28: 500000 | BB28: -40000 | BC28: 8 | BD28: 2026 | BF28: 1000000
A29: 22 | B29: LEP052 | D29: Nguyễn Nam Bình | E29: Production | F29: Riveting Line Operator | G29: 30/09/2025 | H29: =B29&$AM$5 -> LEP05246254 | I29: W | J29: W | K29: W | L29: W | M29: W | O29: W | P29: W | Q29: W | R29: W | S29: W | T29: W | V29: W | W29: W | X29: W | Y29: W | Z29: W | AA29: W | AC29: W | AD29: W | AE29: W | AF29: W | AG29: W | AH29: W | AJ29: W | AK29: W | AL29: W | AM29: W | AN29: 27 | AO29: =COUNTIF(I29:AM29,"W")+COUNTIF(I29:AM29,"W/2 AL/2")*0.5+COUNTIF(I29:AM29,"BT")+COUNTIF(I29:AM29,"N")++COUNTIF(I29:AM29,"W/2 UL/2")*0.5 -> 27 | AP29: =COUNTIF(I29:AM29,"AL")+COUNTIF(I29:AM29,"W/2 AL/2")*0.5+COUNTIF(I29:AM29,"AL/2 UL/2")*0.5 -> 0 | AQ29: =COUNTIF(I29:AM29,"UL")+COUNTIF(I29:AM29,"W/2 UL/2")*0.5+COUNTIF(I29:AM29,"AL/2 UL/2")*0.5 -> 0 | AR29: =COUNTIF(I29:AM29,"PH") -> 0 | AS29: =COUNTIF(I29:AM29,"SL") -> 0 | AT29: =COUNTIF(I29:AM29,"PL") -> 0 | AW29: =(AO29+AP29)*BF29/AN29 -> 1064259 | AX29: =500000*(1-IF(COUNTIF(J29:AM29,"UL")>=2,IF(COUNTIF(J29:AM29,"UL")>=3,1,0.5),0)) -> 500000 | BB29: -40000 | BC29: 8 | BD29: 2026 | BF29: 1064259
A30: 23 | B30: LEP054 | D30: Cao Ngọc Linh | E30: Maintenance (PRO) | F30: Environmental Protection Equipment | G30: 01/10/2025 | H30: =B30&$AM$5 -> LEP05446254 | I30: W | J30: W | K30: W | L30: W | M30: W | O30: W | P30: W | Q30: W | R30: W | S30: W | T30: W | V30: W | W30: W | X30: W | Y30: W | Z30: W | AA30: W | AC30: W | AD30: AL | AE30: W | AF30: W | AG30: W | AH30: W | AJ30: W | AK30: W | AL30: W | AM30: W | AN30: 27 | AO30: =COUNTIF(I30:AM30,"W")+COUNTIF(I30:AM30,"W/2 AL/2")*0.5+COUNTIF(I30:AM30,"BT")+COUNTIF(I30:AM30,"N")++COUNTIF(I30:AM30,"W/2 UL/2")*0.5 -> 26 | AP30: =COUNTIF(I30:AM30,"AL")+COUNTIF(I30:AM30,"W/2 AL/2")*0.5+COUNTIF(I30:AM30,"AL/2 UL/2")*0.5 -> 1 | AQ30: =COUNTIF(I30:AM30,"UL")+COUNTIF(I30:AM30,"W/2 UL/2")*0.5+COUNTIF(I30:AM30,"AL/2 UL/2")*0.5 -> 0 | AR30: =COUNTIF(I30:AM30,"PH") -> 0 | AS30: =COUNTIF(I30:AM30,"SL") -> 0 | AT30: =COUNTIF(I30:AM30,"PL") -> 0 | AW30: =(AO30+AP30)*BF30/AN30 -> 1000000 | AX30: 500000 | AY30: =13000*AO30 -> 338000 | AZ30: 992000 | BB30: -40000 | BC30: 8 | BD30: 2026 | BF30: 1000000
A31: 24 | B31: LEP056 | D31: Đỗ Thế Tài | E31: Production | F31: Painting Line Operator | G31: 02/10/2025 | H31: =B31&$AM$5 -> LEP05646254 | I31: W | J31: W | K31: W | L31: W | M31: W | O31: W | P31: W | Q31: W | R31: W | S31: W | T31: W | V31: W | W31: W | X31: W | Y31: W | Z31: W | AA31: W | AC31: W | AD31: W | AE31: W | AF31: UL | AG31: UL | AH31: W | AJ31: W | AK31: W | AL31: W | AM31: W | AN31: 27 | AO31: =COUNTIF(I31:AM31,"W")+COUNTIF(I31:AM31,"W/2 AL/2")*0.5+COUNTIF(I31:AM31,"BT")+COUNTIF(I31:AM31,"N")++COUNTIF(I31:AM31,"W/2 UL/2")*0.5 -> 25 | AP31: =COUNTIF(I31:AM31,"AL")+COUNTIF(I31:AM31,"W/2 AL/2")*0.5+COUNTIF(I31:AM31,"AL/2 UL/2")*0.5 -> 0 | AQ31: =COUNTIF(I31:AM31,"UL")+COUNTIF(I31:AM31,"W/2 UL/2")*0.5+COUNTIF(I31:AM31,"AL/2 UL/2")*0.5 -> 2 | AR31: =COUNTIF(I31:AM31,"PH") -> 0 | AS31: =COUNTIF(I31:AM31,"SL") -> 0 | AT31: =COUNTIF(I31:AM31,"PL") -> 0 | AW31: =(AO31+AP31)*BF31/AN31 -> 925925.93 | AX31: =500000*(1-IF(COUNTIF(J31:AM31,"UL")>=2,IF(COUNTIF(J31:AM31,"UL")>=3,1,0.5),0)) -> 250000 | AY31: =13000*AO31 -> 325000 | BB31: -40000 | BC31: 8 | BD31: 2026 | BF31: 1000000
